Workbook

Sheet Dashboard_Premissas
A1: MODELO ACTUARIAL DE SAÚDE (RAMO DOENÇA) — SAU & SAG | DASHBOARD & PREMISSAS ACTUARIAIS
A2: Tarifação a custo técnico — mercado angolano. Células a amarelo = inputs editáveis (texto azul). Restantes células são fórmulas. Valores monetários em Kwanzas (Kz) a preços de referência 2026, projectados pela inflação médica. Documento de trabalho sujeito a validação do Actuariado, Médico Assessor e Direcção Técnica (ARSEG).
B3: Legenda: amarelo/azul = input editável | preto = fórmula | verde = ligação entre folhas | verde-claro = resultado final
B4: PAINEL EXECUTIVO — INDICADORES-CHAVE
B5: Indicador | C5: Valor
B6: Inflação médica projectada (medical trend) | C6: =med_trend -> 0.182194
B7: Factor de trend aplicado aos custos | C7: =f_trend -> 1.182194
B8: Carregamentos SAU (e_a+e_c+m) | C8: =load_SAU -> 0.3
B9: Carregamentos SAG (e_a+e_c+m) | C9: =load_SAG -> 0.21
B10: Rácio de sinistralidade alvo SAU | C10: =$D$58 -> 0.64814815
B11: Rácio de sinistralidade alvo SAG | C11: =$E$58 -> 0.75238095
B12: Câmbio USD/AOA | C12: =fx_usd -> 931.27
B13: Calculador — Prémio Total Anual da cotação | C13: =Calculador!C86 -> 2303121.5
B14: Calculador — Prestação na modalidade seleccionada | C14: =Calculador!C95 -> 199603.86
B15: SAG exemplo (censo) — Prémio total anual do grupo | C15: =Matriz_SAG!C161 -> 3.3814811e+08
B16: SAG exemplo — Factor de credibilidade Z | C16: =Matriz_SAG!C185 -> 0.63378288
B17: SAG exemplo — Prémio renovado total a pagar | C17: =Matriz_SAG!C192 -> 4.8346935e+08
B19: DECOMPOSIÇÃO DO PRÉMIO COMERCIAL — PESSOA SEGURA DE REFERÊNCIA (pacote base do plano)
B20: Célula de referência (Género | Escalão) → | C20: M|36-50
B21: Plano | C21: Prémio Puro | D21: Margem de Risco (σ) | E21: Custos Administrativos | F21: Comissões | G21: Margem do Segurador | H21: Impostos e Taxas | I21: Prémio Total | J21: Rácio Sinistr.
B22: SAU Base | C22: =INDEX(Matriz_SAU!$E$61:$E$70,MATCH($C$20,Matriz_SAU!$D$61:$D$70,0)) -> 138719.69 | D22: =C22*sig_SAU -> 11097.575 | E22: =(C22+D22)/(1-load_SAU)*ea_SAU -> 27823.207 | F22: =(C22+D22)/(1-load_SAU)*ec_SAU -> 25682.96 | G22: =(C22+D22)/(1-load_SAU)*m_SAU -> 10701.233 | H22: =(C22+D22)/(1-load_SAU)*tax_SAU -> 2140.2467 | I22: =SUM(C22:H22) -> 216164.92 | J22: =C22/(I22-H22) -> 0.64814815
B23: SAU Conforto | C23: =INDEX(Matriz_SAU!$J$61:$J$70,MATCH($C$20,Matriz_SAU!$D$61:$D$70,0)) -> 384163.62 | D23: =C23*sig_SAU -> 30733.09 | E23: =(C23+D23)/(1-load_SAU)*ea_SAU -> 77052.247 | F23: =(C23+D23)/(1-load_SAU)*ec_SAU -> 71125.151 | G23: =(C23+D23)/(1-load_SAU)*m_SAU -> 29635.48 | H23: =(C23+D23)/(1-load_SAU)*tax_SAU -> 5927.0959 | I23: =SUM(C23:H23) -> 598636.69 | J23: =C23/(I23-H23) -> 0.64814815
B24: SAU Premium | C24: =INDEX(Matriz_SAU!$O$61:$O$70,MATCH($C$20,Matriz_SAU!$D$61:$D$70,0)) -> 920081.41 | D24: =C24*sig_SAU -> 73606.513 | E24: =(C24+D24)/(1-load_SAU)*ea_SAU -> 184542.04 | F24: =(C24+D24)/(1-load_SAU)*ec_SAU -> 170346.5 | G24: =(C24+D24)/(1-load_SAU)*m_SAU -> 70977.709 | H24: =(C24+D24)/(1-load_SAU)*tax_SAU -> 14195.542 | I24: =SUM(C24:H24) -> 1433749.7 | J24: =C24/(I24-H24) -> 0.64814815
B25: SAG Colaboradores | C25: =INDEX(Matriz_SAG!$E$61:$E$70,MATCH($C$20,Matriz_SAG!$D$61:$D$70,0)) -> 333158.54 | D25: =C25*sig_SAG -> 16657.927 | E25: =(C25+D25)/(1-load_SAG)*ea_SAG -> 44280.566 | F25: =(C25+D25)/(1-load_SAG)*ec_SAG -> 30996.396 | G25: =(C25+D25)/(1-load_SAG)*m_SAG -> 17712.226 | H25: =(C25+D25)/(1-load_SAG)*tax_SAG -> 4428.0566 | I25: =SUM(C25:H25) -> 447233.71 | J25: =C25/(I25-H25) -> 0.75238095
B26: SAG Quadros Médios | C26: =INDEX(Matriz_SAG!$J$61:$J$70,MATCH($C$20,Matriz_SAG!$D$61:$D$70,0)) -> 406707.24 | D26: =C26*sig_SAG -> 20335.362 | E26: =(C26+D26)/(1-load_SAG)*ea_SAG -> 54056.026 | F26: =(C26+D26)/(1-load_SAG)*ec_SAG -> 37839.218 | G26: =(C26+D26)/(1-load_SAG)*m_SAG -> 21622.41 | H26: =(C26+D26)/(1-load_SAG)*tax_SAG -> 5405.6026 | I26: =SUM(C26:H26) -> 545965.86 | J26: =C26/(I26-H26) -> 0.75238095
B27: SAG Administração | C27: =INDEX(Matriz_SAG!$O$61:$O$70,MATCH($C$20,Matriz_SAG!$D$61:$D$70,0)) -> 907213.75 | D27: =C27*sig_SAG -> 45360.688 | E27: =(C27+D27)/(1-load_SAG)*ea_SAG -> 120579.04 | F27: =(C27+D27)/(1-load_SAG)*ec_SAG -> 84405.33 | G27: =(C27+D27)/(1-load_SAG)*m_SAG -> 48231.617 | H27: =(C27+D27)/(1-load_SAG)*tax_SAG -> 12057.904 | I27: =SUM(C27:H27) -> 1217848.3 | J27: =C27/(I27-H27) -> 0.75238095
B29: PRÉMIO TOTAL ANUAL POR ESCALÃO ETÁRIO (unisex, ponderado pela exposição) — pacote base
B30: Escalão | C30: SAU Base | D30: SAU Conforto | E30: SAU Premium | F30: SAG Colaboradores | G30: SAG Quadros Médios | H30: SAG Administração
B31: 0-17 | C31: =(INDEX(Matriz_SAU!$H$61:$H$70,MATCH("M|"&$B31,Matriz_SAU!$D$61:$D$70,0))*INDEX(Exp_M,MATCH($B31,Exp_Band,0))+INDEX(Matriz_SAU!$H$61:$H$70,MATCH("F|"&$B31,Matriz_SAU!$D$61:$D$70,0))*INDEX(Exp_F,MATCH($B31,Exp_Band,0)))/(INDEX(Exp_M,MATCH($B31,Exp_Band,0))+INDEX(Exp_F,MATCH($B31,Exp_Band,0))) -> 119291.44 | D31: =(INDEX(Matriz_SAU!$M$61:$M$70,MATCH("M|"&$B31,Matriz_SAU!$D$61:$D$70,0))*INDEX(Exp_M,MATCH($B31,Exp_Band,0))+INDEX(Matriz_SAU!$M$61:$M$70,MATCH("F|"&$B31,Matriz_SAU!$D$61:$D$70,0))*INDEX(Exp_F,MATCH($B31,Exp_Band,0)))/(INDEX(Exp_M,MATCH($B31,Exp_Band,0))+INDEX(Exp_F,MATCH($B31,Exp_Band,0))) -> 389561.17 | E31: =(INDEX(Matriz_SAU!$R$61:$R$70,MATCH("M|"&$B31,Matriz_SAU!$D$61:$D$70,0))*INDEX(Exp_M,MATCH($B31,Exp_Band,0))+INDEX(Matriz_SAU!$R$61:$R$70,MATCH("F|"&$B31,Matriz_SAU!$D$61:$D$70,0))*INDEX(Exp_F,MATCH($B31,Exp_Band,0)))/(INDEX(Exp_M,MATCH($B31,Exp_Band,0))+INDEX(Exp_F,MATCH($B31,Exp_Band,0))) -> 770884.79 | F31: =(INDEX(Matriz_SAG!$H$61:$H$70,MATCH("M|"&$B31,Matriz_SAG!$D$61:$D$70,0))*INDEX(Exp_M,MATCH($B31,Exp_Band,0))+INDEX(Matriz_SAG!$H$61:$H$70,MATCH("F|"&$B31,Matriz_SAG!$D$61:$D$70,0))*INDEX(Exp_F,MATCH($B31,Exp_Band,0)))/(INDEX(Exp_M,MATCH($B31,Exp_Band,0))+INDEX(Exp_F,MATCH($B31,Exp_Band,0))) -> 295365.14 | G31: =(INDEX(Matriz_SAG!$M$61:$M$70,MATCH("M|"&$B31,Matriz_SAG!$D$61:$D$70,0))*INDEX(Exp_M,MATCH($B31,Exp_Band,0))+INDEX(Matriz_SAG!$M$61:$M$70,MATCH("F|"&$B31,Matriz_SAG!$D$61:$D$70,0))*INDEX(Exp_F,MATCH($B31,Exp_Band,0)))/(INDEX(Exp_M,MATCH($B31,Exp_Band,0))+INDEX(Exp_F,MATCH($B31,Exp_Band,0))) -> 356491.93 | H31: =(INDEX(Matriz_SAG!$R$61:$R$70,MATCH("M|"&$B31,Matriz_SAG!$D$61:$D$70,0))*INDEX(Exp_M,MATCH($B31,Exp_Band,0))+INDEX(Matriz_SAG!$R$61:$R$70,MATCH("F|"&$B31,Matriz_SAG!$D$61:$D$70,0))*INDEX(Exp_F,MATCH($B31,Exp_Band,0)))/(INDEX(Exp_M,MATCH($B31,Exp_Band,0))+INDEX(Exp_F,MATCH($B31,Exp_Band,0))) -> 679533.5
B32: 18-35 | C32: =(INDEX(Matriz_SAU!$H$61:$H$70,MATCH("M|"&$B32,Matriz_SAU!$D$61:$D$70,0))*INDEX(Exp_M,MATCH($B32,Exp_Band,0))+INDEX(Matriz_SAU!$H$61:$H$70,MATCH("F|"&$B32,Matriz_SAU!$D$61:$D$70,0))*INDEX(Exp_F,MATCH($B32,Exp_Band,0)))/(INDEX(Exp_M,MATCH($B32,Exp_Band,0))+INDEX(Exp_F,MATCH($B32,Exp_Band,0))) -> 165586.99 | D32: =(INDEX(Matriz_SAU!$M$61:$M$70,MATCH("M|"&$B32,Matriz_SAU!$D$61:$D$70,0))*INDEX(Exp_M,MATCH($B32,Exp_Band,0))+INDEX(Matriz_SAU!$M$61:$M$70,MATCH("F|"&$B32,Matriz_SAU!$D$61:$D$70,0))*INDEX(Exp_F,MATCH($B32,Exp_Band,0)))/(INDEX(Exp_M,MATCH($B32,Exp_Band,0))+INDEX(Exp_F,MATCH($B32,Exp_Band,0))) -> 509083.85 | E32: =(INDEX(Matriz_SAU!$R$61:$R$70,MATCH("M|"&$B32,Matriz_SAU!$D$61:$D$70,0))*INDEX(Exp_M,MATCH($B32,Exp_Band,0))+INDEX(Matriz_SAU!$R$61:$R$70,MATCH("F|"&$B32,Matriz_SAU!$D$61:$D$70,0))*INDEX(Exp_F,MATCH($B32,Exp_Band,0)))/(INDEX(Exp_M,MATCH($B32,Exp_Band,0))+INDEX(Exp_F,MATCH($B32,Exp_Band,0))) -> 1194927.8 | F32: =(INDEX(Matriz_SAG!$H$61:$H$70,MATCH("M|"&$B32,Matriz_SAG!$D$61:$D$70,0))*INDEX(Exp_M,MATCH($B32,Exp_Band,0))+INDEX(Matriz_SAG!$H$61:$H$70,MATCH("F|"&$B32,Matriz_SAG!$D$61:$D$70,0))*INDEX(Exp_F,MATCH($B32,Exp_Band,0)))/(INDEX(Exp_M,MATCH($B32,Exp_Band,0))+INDEX(Exp_F,MATCH($B32,Exp_Band,0))) -> 415037.42 | G32: =(INDEX(Matriz_SAG!$M$61:$M$70,MATCH("M|"&$B32,Matriz_SAG!$D$61:$D$70,0))*INDEX(Exp_M,MATCH($B32,Exp_Band,0))+INDEX(Matriz_SAG!$M$61:$M$70,MATCH("F|"&$B32,Matriz_SAG!$D$61:$D$70,0))*INDEX(Exp_F,MATCH($B32,Exp_Band,0)))/(INDEX(Exp_M,MATCH($B32,Exp_Band,0))+INDEX(Exp_F,MATCH($B32,Exp_Band,0))) -> 511391.49 | H32: =(INDEX(Matriz_SAG!$R$61:$R$70,MATCH("M|"&$B32,Matriz_SAG!$D$61:$D$70,0))*INDEX(Exp_M,MATCH($B32,Exp_Band,0))+INDEX(Matriz_SAG!$R$61:$R$70,MATCH("F|"&$B32,Matriz_SAG!$D$61:$D$70,0))*INDEX(Exp_F,MATCH($B32,Exp_Band,0)))/(INDEX(Exp_M,MATCH($B32,Exp_Band,0))+INDEX(Exp_F,MATCH($B32,Exp_Band,0))) -> 1042517.4
B33: 36-50 | C33: =(INDEX(Matriz_SAU!$H$61:$H$70,MATCH("M|"&$B33,Matriz_SAU!$D$61:$D$70,0))*INDEX(Exp_M,MATCH($B33,Exp_Band,0))+INDEX(Matriz_SAU!$H$61:$H$70,MATCH("F|"&$B33,Matriz_SAU!$D$61:$D$70,0))*INDEX(Exp_F,MATCH($B33,Exp_Band,0)))/(INDEX(Exp_M,MATCH($B33,Exp_Band,0))+INDEX(Exp_F,MATCH($B33,Exp_Band,0))) -> 218143.5 | D33: =(INDEX(Matriz_SAU!$M$61:$M$70,MATCH("M|"&$B33,Matriz_SAU!$D$61:$D$70,0))*INDEX(Exp_M,MATCH($B33,Exp_Band,0))+INDEX(Matriz_SAU!$M$61:$M$70,MATCH("F|"&$B33,Matriz_SAU!$D$61:$D$70,0))*INDEX(Exp_F,MATCH($B33,Exp_Band,0)))/(INDEX(Exp_M,MATCH($B33,Exp_Band,0))+INDEX(Exp_F,MATCH($B33,Exp_Band,0))) -> 635595.12 | E33: =(INDEX(Matriz_SAU!$R$61:$R$70,MATCH("M|"&$B33,Matriz_SAU!$D$61:$D$70,0))*INDEX(Exp_M,MATCH($B33,Exp_Band,0))+INDEX(Matriz_SAU!$R$61:$R$70,MATCH("F|"&$B33,Matriz_SAU!$D$61:$D$70,0))*INDEX(Exp_F,MATCH($B33,Exp_Band,0)))/(INDEX(Exp_M,MATCH($B33,Exp_Band,0))+INDEX(Exp_F,MATCH($B33,Exp_Band,0))) -> 1531164.9 | F33: =(INDEX(Matriz_SAG!$H$61:$H$70,MATCH("M|"&$B33,Matriz_SAG!$D$61:$D$70,0))*INDEX(Exp_M,MATCH($B33,Exp_Band,0))+INDEX(Matriz_SAG!$H$61:$H$70,MATCH("F|"&$B33,Matriz_SAG!$D$61:$D$70,0))*INDEX(Exp_F,MATCH($B33,Exp_Band,0)))/(INDEX(Exp_M,MATCH($B33,Exp_Band,0))+INDEX(Exp_F,MATCH($B33,Exp_Band,0))) -> 486622.33 | G33: =(INDEX(Matriz_SAG!$M$61:$M$70,MATCH("M|"&$B33,Matriz_SAG!$D$61:$D$70,0))*INDEX(Exp_M,MATCH($B33,Exp_Band,0))+INDEX(Matriz_SAG!$M$61:$M$70,MATCH("F|"&$B33,Matriz_SAG!$D$61:$D$70,0))*INDEX(Exp_F,MATCH($B33,Exp_Band,0)))/(INDEX(Exp_M,MATCH($B33,Exp_Band,0))+INDEX(Exp_F,MATCH($B33,Exp_Band,0))) -> 595134.55 | H33: =(INDEX(Matriz_SAG!$R$61:$R$70,MATCH("M|"&$B33,Matriz_SAG!$D$61:$D$70,0))*INDEX(Exp_M,MATCH($B33,Exp_Band,0))+INDEX(Matriz_SAG!$R$61:$R$70,MATCH("F|"&$B33,Matriz_SAG!$D$61:$D$70,0))*INDEX(Exp_F,MATCH($B33,Exp_Band,0)))/(INDEX(Exp_M,MATCH($B33,Exp_Band,0))+INDEX(Exp_F,MATCH($B33,Exp_Band,0))) -> 1296848
B34: 51-65 | C34: =(INDEX(Matriz_SAU!$H$61:$H$70,MATCH("M|"&$B34,Matriz_SAU!$D$61:$D$70,0))*INDEX(Exp_M,MATCH($B34,Exp_Band,0))+INDEX(Matriz_SAU!$H$61:$H$70,MATCH("F|"&$B34,Matriz_SAU!$D$61:$D$70,0))*INDEX(Exp_F,MATCH($B34,Exp_Band,0)))/(INDEX(Exp_M,MATCH($B34,Exp_Band,0))+INDEX(Exp_F,MATCH($B34,Exp_Band,0))) -> 323276.03 | D34: =(INDEX(Matriz_SAU!$M$61:$M$70,MATCH("M|"&$B34,Matriz_SAU!$D$61:$D$70,0))*INDEX(Exp_M,MATCH($B34,Exp_Band,0))+INDEX(Matriz_SAU!$M$61:$M$70,MATCH("F|"&$B34,Matriz_SAU!$D$61:$D$70,0))*INDEX(Exp_F,MATCH($B34,Exp_Band,0)))/(INDEX(Exp_M,MATCH($B34,Exp_Band,0))+INDEX(Exp_F,MATCH($B34,Exp_Band,0))) -> 879736.45 | E34: =(INDEX(Matriz_SAU!$R$61:$R$70,MATCH("M|"&$B34,Matriz_SAU!$D$61:$D$70,0))*INDEX(Exp_M,MATCH($B34,Exp_Band,0))+INDEX(Matriz_SAU!$R$61:$R$70,MATCH("F|"&$B34,Matriz_SAU!$D$61:$D$70,0))*INDEX(Exp_F,MATCH($B34,Exp_Band,0)))/(INDEX(Exp_M,MATCH($B34,Exp_Band,0))+INDEX(Exp_F,MATCH($B34,Exp_Band,0))) -> 2171087.1 | F34: =(INDEX(Matriz_SAG!$H$61:$H$70,MATCH("M|"&$B34,Matriz_SAG!$D$61:$D$70,0))*INDEX(Exp_M,MATCH($B34,Exp_Band,0))+INDEX(Matriz_SAG!$H$61:$H$70,MATCH("F|"&$B34,Matriz_SAG!$D$61:$D$70,0))*INDEX(Exp_F,MATCH($B34,Exp_Band,0)))/(INDEX(Exp_M,MATCH($B34,Exp_Band,0))+INDEX(Exp_F,MATCH($B34,Exp_Band,0))) -> 655760.65 | G34: =(INDEX(Matriz_SAG!$M$61:$M$70,MATCH("M|"&$B34,Matriz_SAG!$D$61:$D$70,0))*INDEX(Exp_M,MATCH($B34,Exp_Band,0))+INDEX(Matriz_SAG!$M$61:$M$70,MATCH("F|"&$B34,Matriz_SAG!$D$61:$D$70,0))*INDEX(Exp_F,MATCH($B34,Exp_Band,0)))/(INDEX(Exp_M,MATCH($B34,Exp_Band,0))+INDEX(Exp_F,MATCH($B34,Exp_Band,0))) -> 802667.69 | H34: =(INDEX(Matriz_SAG!$R$61:$R$70,MATCH("M|"&$B34,Matriz_SAG!$D$61:$D$70,0))*INDEX(Exp_M,MATCH($B34,Exp_Band,0))+INDEX(Matriz_SAG!$R$61:$R$70,MATCH("F|"&$B34,Matriz_SAG!$D$61:$D$70,0))*INDEX(Exp_F,MATCH($B34,Exp_Band,0)))/(INDEX(Exp_M,MATCH($B34,Exp_Band,0))+INDEX(Exp_F,MATCH($B34,Exp_Band,0))) -> 1782199.3
B35: >65 | C35: =(INDEX(Matriz_SAU!$H$61:$H$70,MATCH("M|"&$B35,Matriz_SAU!$D$61:$D$70,0))*INDEX(Exp_M,MATCH($B35,Exp_Band,0))+INDEX(Matriz_SAU!$H$61:$H$70,MATCH("F|"&$B35,Matriz_SAU!$D$61:$D$70,0))*INDEX(Exp_F,MATCH($B35,Exp_Band,0)))/(INDEX(Exp_M,MATCH($B35,Exp_Band,0))+INDEX(Exp_F,MATCH($B35,Exp_Band,0))) -> 473245.18 | D35: =(INDEX(Matriz_SAU!$M$61:$M$70,MATCH("M|"&$B35,Matriz_SAU!$D$61:$D$70,0))*INDEX(Exp_M,MATCH($B35,Exp_Band,0))+INDEX(Matriz_SAU!$M$61:$M$70,MATCH("F|"&$B35,Matriz_SAU!$D$61:$D$70,0))*INDEX(Exp_F,MATCH($B35,Exp_Band,0)))/(INDEX(Exp_M,MATCH($B35,Exp_Band,0))+INDEX(Exp_F,MATCH($B35,Exp_Band,0))) -> 1191572.2 | E35: =(INDEX(Matriz_SAU!$R$61:$R$70,MATCH("M|"&$B35,Matriz_SAU!$D$61:$D$70,0))*INDEX(Exp_M,MATCH($B35,Exp_Band,0))+INDEX(Matriz_SAU!$R$61:$R$70,MATCH("F|"&$B35,Matriz_SAU!$D$61:$D$70,0))*INDEX(Exp_F,MATCH($B35,Exp_Band,0)))/(INDEX(Exp_M,MATCH($B35,Exp_Band,0))+INDEX(Exp_F,MATCH($B35,Exp_Band,0))) -> 2844468.2 | F35: =(INDEX(Matriz_SAG!$H$61:$H$70,MATCH("M|"&$B35,Matriz_SAG!$D$61:$D$70,0))*INDEX(Exp_M,MATCH($B35,Exp_Band,0))+INDEX(Matriz_SAG!$H$61:$H$70,MATCH("F|"&$B35,Matriz_SAG!$D$61:$D$70,0))*INDEX(Exp_F,MATCH($B35,Exp_Band,0)))/(INDEX(Exp_M,MATCH($B35,Exp_Band,0))+INDEX(Exp_F,MATCH($B35,Exp_Band,0))) -> 883607.93 | G35: =(INDEX(Matriz_SAG!$M$61:$M$70,MATCH("M|"&$B35,Matriz_SAG!$D$61:$D$70,0))*INDEX(Exp_M,MATCH($B35,Exp_Band,0))+INDEX(Matriz_SAG!$M$61:$M$70,MATCH("F|"&$B35,Matriz_SAG!$D$61:$D$70,0))*INDEX(Exp_F,MATCH($B35,Exp_Band,0)))/(INDEX(Exp_M,MATCH($B35,Exp_Band,0))+INDEX(Exp_F,MATCH($B35,Exp_Band,0))) -> 1087983.5 | H35: =(INDEX(Matriz_SAG!$R$61:$R$70,MATCH("M|"&$B35,Matriz_SAG!$D$61:$D$70,0))*INDEX(Exp_M,MATCH($B35,Exp_Band,0))+INDEX(Matriz_SAG!$R$61:$R$70,MATCH("F|"&$B35,Matriz_SAG!$D$61:$D$70,0))*INDEX(Exp_F,MATCH($B35,Exp_Band,0)))/(INDEX(Exp_M,MATCH($B35,Exp_Band,0))+INDEX(Exp_F,MATCH($B35,Exp_Band,0))) -> 2316177.2
B36: A. PARÂMETROS MACROECONÓMICOS E INFLAÇÃO MÉDICA (MEDICAL TREND) — ANGOLA
B37: Parâmetro | C37: Código | D37: Valor | E37: Fonte / Racional
B38: Data de referência dos custos médicos (preços base) | C38: dt_base | D38: 46203 | E38: Tabelas de preços da rede convencionada de Luanda, 1.º semestre 2026
B39: Taxa de câmbio USD/AOA | C39: fx_usd | D39: 931.27 | E39: Câmbio de mercado 01/10/2026 ≈ 931 Kz/USD (Wise / BNA). Actualizar trimestralmente
B40: Inflação geral IPC Angola (homóloga) | C40: cpi | D40: 0.109 | E40: INE Angola: 10,88% homóloga em Maio 2026 (BNA projecta ~13,5% média 2026)
B41: Excesso de inflação médica sobre IPC | C41: med_excess | D41: 0.04 | E41: Tecnologia, procura induzida, escassez de especialistas e salários clínicos
B42: Componente cambial (fármacos/dispositivos importados) | C42: fx_comp | D42: 0.025 | E42: Pass-through da depreciação do Kz em consumíveis e medicamentos importados
...

Sheet Matriz_SAU
A1: MATRIZ TARIFÁRIA SAU — SEGURO DE SAÚDE INDIVIDUAL E FAMILIAR | TARIFAÇÃO A CUSTO TÉCNICO
A2: Construção da tarifa por Pessoa Segura / anuidade, por Plano (Base = Hospitalização; Conforto = Médio; Premium = Superior) e por cobertura. Estatuto: B = base incluída, O = opcional (extensão modular), — = não disponível. Capitais conforme ficha técnica SAU (editáveis).
A3: Parâmetros aplicados → | B3: σ | C3: =sig_SAU -> 0.08 | D3: e_a+e_c+m | E3: =load_SAU -> 0.3 | F3: Impostos | G3: =tax_SAU -> 0.01 | H3: Trend | I3: =f_trend -> 1.182194
A4: Fórmulas: Prémio Puro = λ × μ ajustado × Trend × Factor LEV | Prémio de Risco Técnico = Prémio Puro × (1+σ) | Prémio Comercial Bruto = PRT / (1 − (e_a+e_c+m)) | Prémio Total = PCB × (1 + impostos). Valores por Pessoa Segura/anuidade na célula de referência da cobertura (ver Premissas §D).
A5: Chave | B5: Plano / Categoria | C5: Código | D5: Cobertura | E5: Grupo | F5: Estatuto (B/O/—) | G5: Capital / Sublimite anual (Kz) | H5: Frequência λ | I5: μ Ponderado (Kz) | J5: Factor de Rede | K5: Dedução sublimite quarto (Kz) | L5: μ Ajustado (Kz) | M5: Factor Trend | N5: Custo médio por sinistrado (Kz) | O5: CV | P5: σ ln | Q5: μ ln | R5: Factor Limitação de Capital (LEV) | S5: PRÉMIO PURO (Kz) | T5: Carregamento Volatilidade σ (Kz) | U5: PRÉMIO DE RISCO TÉCNICO (Kz) | V5: PRÉMIO COMERCIAL BRUTO (Kz) | W5: Despesas Gestão e_a (Kz) | X5: Comissões e_c (Kz) | Y5: Margem m (Kz) | Z5: Impostos e Taxas (Kz) | AA5: PRÉMIO TOTAL ANUAL (Kz) | AB5: Taxa de Risco Pura (‰ do capital)
A6: =B6&"|"&C6 -> Base|HOSP_INT | B6: Base | C6: HOSP_INT | D6: =INDEX(Cov_Nome,MATCH(C6,Cov_Cod,0)) -> Internamento Hospitalar Médico (incl. malária grave) | E6: =INDEX(Cov_Grupo,MATCH(C6,Cov_Cod,0)) -> Principal | F6: B | G6: 5000000 | H6: =INDEX(Cov_Lambda,MATCH(C6,Cov_Cod,0)) -> 0.045 | I6: =INDEX(Cov_Mu,MATCH(C6,Cov_Cod,0)) -> 854500 | J6: =IF(INDEX(Cov_FR,MATCH(C6,Cov_Cod,0))="S",INDEX(PF_Factor,MATCH("SAU|"&B6,PF_Key,0)),1) -> 0.85 | K6: =IF(C6="HOSP_INT",los_int,IF(C6="HOSP_CIR",los_cir,0))*MAX(0,room_ref*J6-INDEX(PF_Room,MATCH("SAU|"&B6,PF_Key,0))) -> 74000 | L6: =MAX(0,I6*J6-K6) -> 652325 | M6: =f_trend -> 1.182194 | N6: =H6*L6*M6/(1-EXP(-H6)) -> 788656.26 | O6: =INDEX(Cov_CV,MATCH(C6,Cov_Cod,0)) -> 1.5 | P6: =SQRT(LN(1+O6^2)) -> 1.0856588 | Q6: =LN(N6)-P6^2/2 -> 12.988758 | R6: =IF(G6<=0,1,NORMSDIST((LN(G6)-Q6-P6^2)/P6)+G6/N6*(1-NORMSDIST((LN(G6)-Q6)/P6))) -> 0.95535503 | S6: =IF(F6="—",0,H6*L6*M6*R6) -> 33153.553 | T6: =S6*sig_SAU -> 2652.2843 | U6: =S6+T6 -> 35805.838 | V6: =U6/(1-load_SAU) -> 51151.197 | W6: =V6*ea_SAU -> 6649.6556 | X6: =V6*ec_SAU -> 6138.1436 | Y6: =V6*m_SAU -> 2557.5598 | Z6: =V6*tax_SAU -> 511.51197 | AA6: =V6+Z6 -> 51662.709 | AB6: =IF(G6>0,S6/G6*1000,"n.a.") -> 6.6307107
A7: =B7&"|"&C7 -> Base|HOSP_CIR | B7: Base | C7: HOSP_CIR | D7: =INDEX(Cov_Nome,MATCH(C7,Cov_Cod,0)) -> Cirurgia (com internamento e de ambulatório) | E7: =INDEX(Cov_Grupo,MATCH(C7,Cov_Cod,0)) -> Principal | F7: B | G7: 5000000 | H7: =INDEX(Cov_Lambda,MATCH(C7,Cov_Cod,0)) -> 0.024 | I7: =INDEX(Cov_Mu,MATCH(C7,Cov_Cod,0)) -> 2032500 | J7: =IF(INDEX(Cov_FR,MATCH(C7,Cov_Cod,0))="S",INDEX(PF_Factor,MATCH("SAU|"&B7,PF_Key,0)),1) -> 0.85 | K7: =IF(C7="HOSP_INT",los_int,IF(C7="HOSP_CIR",los_cir,0))*MAX(0,room_ref*J7-INDEX(PF_Room,MATCH("SAU|"&B7,PF_Key,0))) -> 46250 | L7: =MAX(0,I7*J7-K7) -> 1681375 | M7: =f_trend -> 1.182194 | N7: =H7*L7*M7/(1-EXP(-H7)) -> 2011659.4 | O7: =INDEX(Cov_CV,MATCH(C7,Cov_Cod,0)) -> 1.3 | P7: =SQRT(LN(1+O7^2)) -> 0.99475685 | Q7: =LN(N7)-P7^2/2 -> 14.0197 | R7: =IF(G7<=0,1,NORMSDIST((LN(G7)-Q7-P7^2)/P7)+G7/N7*(1-NORMSDIST((LN(G7)-Q7)/P7))) -> 0.85804276 | S7: =IF(F7="—",0,H7*L7*M7*R7) -> 40932.994 | T7: =S7*sig_SAU -> 3274.6395 | U7: =S7+T7 -> 44207.633 | V7: =U7/(1-load_SAU) -> 63153.762 | W7: =V7*ea_SAU -> 8209.989 | X7: =V7*ec_SAU -> 7578.4514 | Y7: =V7*m_SAU -> 3157.6881 | Z7: =V7*tax_SAU -> 631.53762 | AA7: =V7+Z7 -> 63785.3 | AB7: =IF(G7>0,S7/G7*1000,"n.a.") -> 8.1865988
A8: =B8&"|"&C8 -> Base|HOSP_UCI | B8: Base | C8: HOSP_UCI | D8: =INDEX(Cov_Nome,MATCH(C8,Cov_Cod,0)) -> Cuidados Intensivos (UCI) | E8: =INDEX(Cov_Grupo,MATCH(C8,Cov_Cod,0)) -> Principal | F8: B | G8: =INDEX(PF_UCI,MATCH("SAU|"&B8,PF_Key,0)) -> 2500000 | H8: =INDEX(Cov_Lambda,MATCH(C8,Cov_Cod,0)) -> 0.0035 | I8: =INDEX(Cov_Mu,MATCH(C8,Cov_Cod,0)) -> 2835000 | J8: =IF(INDEX(Cov_FR,MATCH(C8,Cov_Cod,0))="S",INDEX(PF_Factor,MATCH("SAU|"&B8,PF_Key,0)),1) -> 0.85 | K8: =IF(C8="HOSP_INT",los_int,IF(C8="HOSP_CIR",los_cir,0))*MAX(0,room_ref*J8-INDEX(PF_Room,MATCH("SAU|"&B8,PF_Key,0))) -> 0 | L8: =MAX(0,I8*J8-K8) -> 2409750 | M8: =f_trend -> 1.182194 | N8: =H8*L8*M8/(1-EXP(-H8)) -> 2853780.3 | O8: =INDEX(Cov_CV,MATCH(C8,Cov_Cod,0)) -> 1.2 | P8: =SQRT(LN(1+O8^2)) -> 0.94445648 | Q8: =LN(N8)-P8^2/2 -> 14.418156 | R8: =IF(G8<=0,1,NORMSDIST((LN(G8)-Q8-P8^2)/P8)+G8/N8*(1-NORMSDIST((LN(G8)-Q8)/P8))) -> 0.59420086 | S8: =IF(F8="—",0,H8*L8*M8*R8) -> 5924.6412 | T8: =S8*sig_SAU -> 473.9713 | U8: =S8+T8 -> 6398.6125 | V8: =U8/(1-load_SAU) -> 9140.875 | W8: =V8*ea_SAU -> 1188.3138 | X8: =V8*ec_SAU -> 1096.905 | Y8: =V8*m_SAU -> 457.04375 | Z8: =V8*tax_SAU -> 91.40875 | AA8: =V8+Z8 -> 9232.2838 | AB8: =IF(G8>0,S8/G8*1000,"n.a.") -> 2.3698565
A9: =B9&"|"&C9 -> Base|AMB_CONS | B9: Base | C9: AMB_CONS | D9: =INDEX(Cov_Nome,MATCH(C9,Cov_Cod,0)) -> Consultas de Clínica Geral e Especialidade (incl. teleconsulta) | E9: =INDEX(Cov_Grupo,MATCH(C9,Cov_Cod,0)) -> Principal | F9: O | G9: 1500000 | H9: =INDEX(Cov_Lambda,MATCH(C9,Cov_Cod,0)) -> 2.6 | I9: =INDEX(Cov_Mu,MATCH(C9,Cov_Cod,0)) -> 24000 | J9: =IF(INDEX(Cov_FR,MATCH(C9,Cov_Cod,0))="S",INDEX(PF_Factor,MATCH("SAU|"&B9,PF_Key,0)),1) -> 0.85 | K9: =IF(C9="HOSP_INT",los_int,IF(C9="HOSP_CIR",los_cir,0))*MAX(0,room_ref*J9-INDEX(PF_Room,MATCH("SAU|"&B9,PF_Key,0))) -> 0 | L9: =MAX(0,I9*J9-K9) -> 20400 | M9: =f_trend -> 1.182194 | N9: =H9*L9*M9/(1-EXP(-H9)) -> 67734.45 | O9: =INDEX(Cov_CV,MATCH(C9,Cov_Cod,0)) -> 1 | P9: =SQRT(LN(1+O9^2)) -> 0.83255461 | Q9: =LN(N9)-P9^2/2 -> 10.776777 | R9: =IF(G9<=0,1,NORMSDIST((LN(G9)-Q9-P9^2)/P9)+G9/N9*(1-NORMSDIST((LN(G9)-Q9)/P9))) -> 0.9999138 | S9: =IF(F9="—",0,H9*L9*M9*R9) -> 62698.165 | T9: =S9*sig_SAU -> 5015.8532 | U9: =S9+T9 -> 67714.018 | V9: =U9/(1-load_SAU) -> 96734.311 | W9: =V9*ea_SAU -> 12575.46 | X9: =V9*ec_SAU -> 11608.117 | Y9: =V9*m_SAU -> 4836.7156 | Z9: =V9*tax_SAU -> 967.34311 | AA9: =V9+Z9 -> 97701.654 | AB9: =IF(G9>0,S9/G9*1000,"n.a.") -> 41.798776
A10: =B10&"|"&C10 -> Base|AMB_MCDT | B10: Base | C10: AMB_MCDT | D10: =INDEX(Cov_Nome,MATCH(C10,Cov_Cod,0)) -> MCDT — Exames, Análises e Imagiologia | E10: =INDEX(Cov_Grupo,MATCH(C10,Cov_Cod,0)) -> Principal | F10: O | G10: 1500000 | H10: =INDEX(Cov_Lambda,MATCH(C10,Cov_Cod,0)) -> 3.8 | I10: =INDEX(Cov_Mu,MATCH(C10,Cov_Cod,0)) -> 14600 | J10: =IF(INDEX(Cov_FR,MATCH(C10,Cov_Cod,0))="S",INDEX(PF_Factor,MATCH("SAU|"&B10,PF_Key,0)),1) -> 0.85 | K10: =IF(C10="HOSP_INT",los_int,IF(C10="HOSP_CIR",los_cir,0))*MAX(0,room_ref*J10-INDEX(PF_Room,MATCH("SAU|"&B10,PF_Key,0))) -> 0 | L10: =MAX(0,I10*J10-K10) -> 12410 | M10: =f_trend -> 1.182194 | N10: =H10*L10*M10/(1-EXP(-H10)) -> 57025.612 | O10: =INDEX(Cov_CV,MATCH(C10,Cov_Cod,0)) -> 1.5 | P10: =SQRT(LN(1+O10^2)) -> 1.0856588 | Q10: =LN(N10)-P10^2/2 -> 10.361928 | R10: =IF(G10<=0,1,NORMSDIST((LN(G10)-Q10-P10^2)/P10)+G10/N10*(1-NORMSDIST((LN(G10)-Q10)/P10))) -> 0.99820307 | S10: =IF(F10="—",0,H10*L10*M10*R10) -> 55649.726 | T10: =S10*sig_SAU -> 4451.9781 | U10: =S10+T10 -> 60101.704 | V10: =U10/(1-load_SAU) -> 85859.577 | W10: =V10*ea_SAU -> 11161.745 | X10: =V10*ec_SAU -> 10303.149 | Y10: =V10*m_SAU -> 4292.9789 | Z10: =V10*tax_SAU -> 858.59577 | AA10: =V10+Z10 -> 86718.173 | AB10: =IF(G10>0,S10/G10*1000,"n.a.") -> 37.099817
A11: =B11&"|"&C11 -> Base|MAL | B11: Base | C11: MAL | D11: =INDEX(Cov_Nome,MATCH(C11,Cov_Cod,0)) -> Malária e Doenças Endémicas (ambulatório) | E11: =INDEX(Cov_Grupo,MATCH(C11,Cov_Cod,0)) -> Principal | F11: O | G11: 1500000 | H11: =INDEX(Cov_Lambda,MATCH(C11,Cov_Cod,0)) -> 0.3 | I11: =INDEX(Cov_Mu,MATCH(C11,Cov_Cod,0)) -> 36500 | J11: =IF(INDEX(Cov_FR,MATCH(C11,Cov_Cod,0))="S",INDEX(PF_Factor,MATCH("SAU|"&B11,PF_Key,0)),1) -> 0.85 | K11: =IF(C11="HOSP_INT",los_int,IF(C11="HOSP_CIR",los_cir,0))*MAX(0,room_ref*J11-INDEX(PF_Room,MATCH("SAU|"&B11,PF_Key,0))) -> 0 | L11: =MAX(0,I11*J11-K11) -> 31025 | M11: =f_trend -> 1.182194 | N11: =H11*L11*M11/(1-EXP(-H11)) -> 42453.874 | O11: =INDEX(Cov_CV,MATCH(C11,Cov_Cod,0)) -> 0.8 | P11: =SQRT(LN(1+O11^2)) -> 0.70334646 | Q11: =LN(N11)-P11^2/2 -> 10.408825 | R11: =IF(G11<=0,1,NORMSDIST((LN(G11)-Q11-P11^2)/P11)+G11/N11*(1-NORMSDIST((LN(G11)-Q11)/P11))) -> 0.99999985 | S11: =IF(F11="—",0,H11*L11*M11*R11) -> 11003.269 | T11: =S11*sig_SAU -> 880.26152 | U11: =S11+T11 -> 11883.531 | V11: =U11/(1-load_SAU) -> 16976.472 | W11: =V11*ea_SAU -> 2206.9414 | X11: =V11*ec_SAU -> 2037.1767 | Y11: =V11*m_SAU -> 848.82361 | Z11: =V11*tax_SAU -> 169.76472 | AA11: =V11+Z11 -> 17146.237 | AB11: =IF(G11>0,S11/G11*1000,"n.a.") -> 7.3355127
A12: =B12&"|"&C12 -> Base|MAT | B12: Base | C12: MAT | D12: =INDEX(Cov_Nome,MATCH(C12,Cov_Cod,0)) -> Maternidade e Parto (Normal e Cesariana) | E12: =INDEX(Cov_Grupo,MATCH(C12,Cov_Cod,0)) -> Principal | F12: — | G12: 0 | H12: =INDEX(Cov_Lambda,MATCH(C12,Cov_Cod,0)) -> 0.075 | I12: =INDEX(Cov_Mu,MATCH(C12,Cov_Cod,0)) -> 885640 | J12: =IF(INDEX(Cov_FR,MATCH(C12,Cov_Cod,0))="S",INDEX(PF_Factor,MATCH("SAU|"&B12,PF_Key,0)),1) -> 0.85 | K12: =IF(C12="HOSP_INT",los_int,IF(C12="HOSP_CIR",los_cir,0))*MAX(0,room_ref*J12-INDEX(PF_Room,MATCH("SAU|"&B12,PF_Key,0))) -> 0 | L12: =MAX(0,I12*J12-K12) -> 752794 | M12: =f_trend -> 1.182194 | N12: =H12*L12*M12/(1-EXP(-H12)) -> 923738.74 | O12: =INDEX(Cov_CV,MATCH(C12,Cov_Cod,0)) -> 0.5 | P12: =SQRT(LN(1+O12^2)) -> 0.47238073 | Q12: =LN(N12)-P12^2/2 -> 13.624613 | R12: =IF(G12<=0,1,NORMSDIST((LN(G12)-Q12-P12^2)/P12)+G12/N12*(1-NORMSDIST((LN(G12)-Q12)/P12))) -> 1 | S12: =IF(F12="—",0,H12*L12*M12*R12) -> 0 | T12: =S12*sig_SAU -> 0 | U12: =S12+T12 -> 0 | V12: =U12/(1-load_SAU) -> 0 | W12: =V12*ea_SAU -> 0 | X12: =V12*ec_SAU -> 0 | Y12: =V12*m_SAU -> 0 | Z12: =V12*tax_SAU -> 0 | AA12: =V12+Z12 -> 0 | AB12: =IF(G12>0,S12/G12*1000,"n.a.") -> n.a.
A13: =B13&"|"&C13 -> Base|URG | B13: Base | C13: URG | D13: =INDEX(Cov_Nome,MATCH(C13,Cov_Cod,0)) -> Urgência Hospitalar | E13: =INDEX(Cov_Grupo,MATCH(C13,Cov_Cod,0)) -> Principal | F13: B | G13: 250000 | H13: =INDEX(Cov_Lambda,MATCH(C13,Cov_Cod,0)) -> 0.42 | I13: =INDEX(Cov_Mu,MATCH(C13,Cov_Cod,0)) -> 43300 | J13: =IF(INDEX(Cov_FR,MATCH(C13,Cov_Cod,0))="S",INDEX(PF_Factor,MATCH("SAU|"&B13,PF_Key,0)),1) -> 0.85 | K13: =IF(C13="HOSP_INT",los_int,IF(C13="HOSP_CIR",los_cir,0))*MAX(0,room_ref*J13-INDEX(PF_Room,MATCH("SAU|"&B13,PF_Key,0))) -> 0 | L13: =MAX(0,I13*J13-K13) -> 36805 | M13: =f_trend -> 1.182194 | N13: =H13*L13*M13/(1-EXP(-H13)) -> 53285.621 | O13: =INDEX(Cov_CV,MATCH(C13,Cov_Cod,0)) -> 1 | P13: =SQRT(LN(1+O13^2)) -> 0.83255461 | Q13: =LN(N13)-P13^2/2 -> 10.536848 | R13: =IF(G13<=0,1,NORMSDIST((LN(G13)-Q13-P13^2)/P13)+G13/N13*(1-NORMSDIST((LN(G13)-Q13)/P13))) -> 0.97914522 | S13: =IF(F13="—",0,H13*L13*M13*R13) -> 17893.363 | T13: =S13*sig_SAU -> 1431.469 | U13: =S13+T13 -> 19324.832 | V13: =U13/(1-load_SAU) -> 27606.903 | W13: =V13*ea_SAU -> 3588.8974 | X13: =V13*ec_SAU -> 3312.8283 | Y13: =V13*m_SAU -> 1380.3451 | Z13: =V13*tax_SAU -> 276.06903 | AA13: =V13+Z13 -> 27882.972 | AB13: =IF(G13>0,S13/G13*1000,"n.a.") -> 71.573452
A14: =B14&"|"&C14 -> Base|AMBUL | B14: Base | C14: AMBUL | D14: =INDEX(Cov_Nome,MATCH(C14,Cov_Cod,0)) -> Transporte em Ambulância / Emergência Médica | E14: =INDEX(Cov_Grupo,MATCH(C14,Cov_Cod,0)) -> Principal | F14: B | G14: 150000 | H14: =INDEX(Cov_Lambda,MATCH(C14,Cov_Cod,0)) -> 0.018 | I14: =INDEX(Cov_Mu,MATCH(C14,Cov_Cod,0)) -> 76000 | J14: =IF(INDEX(Cov_FR,MATCH(C14,Cov_Cod,0))="S",INDEX(PF_Factor,MATCH("SAU|"&B14,PF_Key,0)),1) -> 1 | K14: =IF(C14="HOSP_INT",los_int,IF(C14="HOSP_CIR",los_cir,0))*MAX(0,room_ref*J14-INDEX(PF_Room,MATCH("SAU|"&B14,PF_Key,0))) -> 0 | L14: =MAX(0,I14*J14-K14) -> 76000 | M14: =f_trend -> 1.182194 | N14: =H14*L14*M14/(1-EXP(-H14)) -> 90657.791 | O14: =INDEX(Cov_CV,MATCH(C14,Cov_Cod,0)) -> 0.6 | P14: =SQRT(LN(1+O14^2)) -> 0.55451303 | Q14: =LN(N14)-P14^2/2 -> 11.261105 | R14: =IF(G14<=0,1,NORMSDIST((LN(G14)-Q14-P14^2)/P14)+G14/N14*(1-NORMSDIST((LN(G14)-Q14)/P14))) -> 0.93106611 | S14: =IF(F14="—",0,H14*L14*M14*R14) -> 1505.7587 | T14: =S14*sig_SAU -> 120.46069 | U14: =S14+T14 -> 1626.2193 | V14: =U14/(1-load_SAU) -> 2323.1705 | W14: =V14*ea_SAU -> 302.01216 | X14: =V14*ec_SAU -> 278.78046 | Y14: =V14*m_SAU -> 116.15852 | Z14: =V14*tax_SAU -> 23.231705 | AA14: =V14+Z14 -> 2346.4022 | AB14: =IF(G14>0,S14/G14*1000,"n.a.") -> 10.038391
A15: =B15&"|"&C15 -> Base|MED | B15: Base | C15: MED | D15: =INDEX(Cov_Nome,MATCH(C15,Cov_Cod,0)) -> Medicamentos em Ambulatório (Farmácia) | E15: =INDEX(Cov_Grupo,MATCH(C15,Cov_Cod,0)) -> Principal | F15: — | G15: 0 | H15: =INDEX(Cov_Lambda,MATCH(C15,Cov_Cod,0)) -> 3.4 | I15: =INDEX(Cov_Mu,MATCH(C15,Cov_Cod,0)) -> 17400 | J15: =IF(INDEX(Cov_FR,MATCH(C15,Cov_Cod,0))="S",INDEX(PF_Factor,MATCH("SAU|"&B15,PF_Key,0)),1) -> 1 | K15: =IF(C15="HOSP_INT",los_int,IF(C15="HOSP_CIR",los_cir,0))*MAX(0,room_ref*J15-INDEX(PF_Room,MATCH("SAU|"&B15,PF_Key,0))) -> 0 | L15: =MAX(0,I15*J15-K15) -> 17400 | M15: =f_trend -> 1.182194 | N15: =H15*L15*M15/(1-EXP(-H15)) -> 72353.262 | O15: =INDEX(Cov_CV,MATCH(C15,Cov_Cod,0)) -> 1.2 | P15: =SQRT(LN(1+O15^2)) -> 0.94445648 | Q15: =LN(N15)-P15^2/2 -> 10.743317 | R15: =IF(G15<=0,1,NORMSDIST((LN(G15)-Q15-P15^2)/P15)+G15/N15*(1-NORMSDIST((LN(G15)-Q15)/P15))) -> 1 | S15: =IF(F15="—",0,H15*L15*M15*R15) -> 0 | T15: =S15*sig_SAU -> 0 | U15: =S15+T15 -> 0 | V15: =U15/(1-load_SAU) -> 0 | W15: =V15*ea_SAU -> 0 | X15: =V15*ec_SAU -> 0 | Y15: =V15*m_SAU -> 0 | Z15: =V15*tax_SAU -> 0 | AA15: =V15+Z15 -> 0 | AB15: =IF(G15>0,S15/G15*1000,"n.a.") -> n.a.
A16: =B16&"|"&C16 -> Base|DENT | B16: Base | C16: DENT | D16: =INDEX(Cov_Nome,MATCH(C16,Cov_Cod,0)) -> Estomatologia (tratamentos) | E16: =INDEX(Cov_Grupo,MATCH(C16,Cov_Cod,0)) -> Extensão | F16: — | G16: 0 | H16: =INDEX(Cov_Lambda,MATCH(C16,Cov_Cod,0)) -> 0.85 | I16: =INDEX(Cov_Mu,MATCH(C16,Cov_Cod,0)) -> 34500 | J16: =IF(INDEX(Cov_FR,MATCH(C16,Cov_Cod,0))="S",INDEX(PF_Factor,MATCH("SAU|"&B16,PF_Key,0)),1) -> 0.85 | K16: =IF(C16="HOSP_INT",los_int,IF(C16="HOSP_CIR",los_cir,0))*MAX(0,room_ref*J16-INDEX(PF_Room,MATCH("SAU|"&B16,PF_Key,0))) -> 0 | L16: =MAX(0,I16*J16-K16) -> 29325 | M16: =f_trend -> 1.182194 | N16: =H16*L16*M16/(1-EXP(-H16)) -> 51464.254 | O16: =INDEX(Cov_CV,MATCH(C16,Cov_Cod,0)) -> 1 | P16: =SQRT(LN(1+O16^2)) -> 0.83255461 | Q16: =LN(N16)-P16^2/2 -> 10.502069 | R16: =IF(G16<=0,1,NORMSDIST((LN(G16)-Q16-P16^2)/P16)+G16/N16*(1-NORMSDIST((LN(G16)-Q16)/P16))) -> 1 | S16: =IF(F16="—",0,H16*L16*M16*R16) -> 0 | T16: =S16*sig_SAU -> 0 | U16: =S16+T16 -> 0 | V16: =U16/(1-load_SAU) -> 0 | W16: =V16*ea_SAU -> 0 | X16: =V16*ec_SAU -> 0 | Y16: =V16*m_SAU -> 0 | Z16: =V16*tax_SAU -> 0 | AA16: =V16+Z16 -> 0 | AB16: =IF(G16>0,S16/G16*1000,"n.a.") -> n.a.
A17: =B17&"|"&C17 -> Base|PROT | B17: Base | C17: PROT | D17: =INDEX(Cov_Nome,MATCH(C17,Cov_Cod,0)) -> Próteses Dentárias | E17: =INDEX(Cov_Grupo,MATCH(C17,Cov_Cod,0)) -> Extensão | F17: — | G17: 0 | H17: =INDEX(Cov_Lambda,MATCH(C17,Cov_Cod,0)) -> 0.02 | I17: =INDEX(Cov_Mu,MATCH(C17,Cov_Cod,0)) -> 304000 | J17: =IF(INDEX(Cov_FR,MATCH(C17,Cov_Cod,0))="S",INDEX(PF_Factor,MATCH("SAU|"&B17,PF_Key,0)),1) -> 1 | K17: =IF(C17="HOSP_INT",los_int,IF(C17="HOSP_CIR",los_cir,0))*MAX(0,room_ref*J17-INDEX(PF_Room,MATCH("SAU|"&B17,PF_Key,0))) -> 0 | L17: =MAX(0,I17*J17-K17) -> 304000 | M17: =f_trend -> 1.182194 | N17: =H17*L17*M17/(1-EXP(-H17)) -> 362992.83 | O17: =INDEX(Cov_CV,MATCH(C17,Cov_Cod,0)) -> 0.7 | P17: =SQRT(LN(1+O17^2)) -> 0.63148723 | Q17: =LN(N17)-P17^2/2 -> 12.60275 | R17: =IF(G17<=0,1,NORMSDIST((LN(G17)-Q17-P17^2)/P17)+G17/N17*(1-NORMSDIST((LN(G17)-Q17)/P17))) -> 1 | S17: =IF(F17="—",0,H17*L17*M17*R17) -> 0 | T17: =S17*sig_SAU -> 0 | U17: =S17+T17 -> 0 | V17: =U17/(1-load_SAU) -> 0 | W17: =V17*ea_SAU -> 0 | X17: =V17*ec_SAU -> 0 | Y17: =V17*m_SAU -> 0 | Z17: =V17*tax_SAU -> 0 | AA17: =V17+Z17 -> 0 | AB17: =IF(G17>0,S17/G17*1000,"n.a.") -> n.a.
A18: =B18&"|"&C18 -> Base|OPT | B18: Base | C18: OPT | D18: =INDEX(Cov_Nome,MATCH(C18,Cov_Cod,0)) -> Óptica — Lentes e Armações | E18: =INDEX(Cov_Grupo,MATCH(C18,Cov_Cod,0)) -> Extensão | F18: — | G18: 0 | H18: =INDEX(Cov_Lambda,MATCH(C18,Cov_Cod,0)) -> 0.22 | I18: =INDEX(Cov_Mu,MATCH(C18,Cov_Cod,0)) -> 102500 | J18: =IF(INDEX(Cov_FR,MATCH(C18,Cov_Cod,0))="S",INDEX(PF_Factor,MATCH("SAU|"&B18,PF_Key,0)),1) -> 1 | K18: =IF(C18="HOSP_INT",los_int,IF(C18="HOSP_CIR",los_cir,0))*MAX(0,room_ref*J18-INDEX(PF_Room,MATCH("SAU|"&B18,PF_Key,0))) -> 0 | L18: =MAX(0,I18*J18-K18) -> 102500 | M18: =f_trend -> 1.182194 | N18: =H18*L18*M18/(1-EXP(-H18)) -> 134992.47 | O18: =INDEX(Cov_CV,MATCH(C18,Cov_Cod,0)) -> 0.5 | P18: =SQRT(LN(1+O18^2)) -> 0.47238073 | Q18: =LN(N18)-P18^2/2 -> 11.701402 | R18: =IF(G18<=0,1,NORMSDIST((LN(G18)-Q18-P18^2)/P18)+G18/N18*(1-NORMSDIST((LN(G18)-Q18)/P18))) -> 1 | S18: =IF(F18="—",0,H18*L18*M18*R18) -> 0 | T18: =S18*sig_SAU -> 0 | U18: =S18+T18 -> 0 | V18: =U18/(1-load_SAU) -> 0 | W18: =V18*ea_SAU -> 0 | X18: =V18*ec_SAU -> 0 | Y18: =V18*m_SAU -> 0 | Z18: =V18*tax_SAU -> 0 | AA18: =V18+Z18 -> 0 | AB18: =IF(G18>0,S18/G18*1000,"n.a.") -> n.a.
A19: =B19&"|"&C19 -> Base|PREV | B19: Base | C19: PREV | D19: =INDEX(Cov_Nome,MATCH(C19,Cov_Cod,0)) -> Medicina Preventiva e Check-up Anual | E19: =INDEX(Cov_Grupo,MATCH(C19,Cov_Cod,0)) -> Extensão | F19: — | G19: 0 | H19: =INDEX(Cov_Lambda,MATCH(C19,Cov_Cod,0)) -> 0.55 | I19: =INDEX(Cov_Mu,MATCH(C19,Cov_Cod,0)) -> 76000 | J19: =IF(INDEX(Cov_FR,MATCH(C19,Cov_Cod,0))="S",INDEX(PF_Factor,MATCH("SAU|"&B19,PF_Key,0)),1) -> 1 | K19: =IF(C19="HOSP_INT",los_int,IF(C19="HOSP_CIR",los_cir,0))*MAX(0,room_ref*J19-INDEX(PF_Room,MATCH("SAU|"&B19,PF_Key,0))) -> 0 | L19: =MAX(0,I19*J19-K19) -> 76000 | M19: =f_trend -> 1.182194 | N19: =H19*L19*M19/(1-EXP(-H19)) -> 116808.15 | O19: =INDEX(Cov_CV,MATCH(C19,Cov_Cod,0)) -> 0.3 | P19: =SQRT(LN(1+O19^2)) -> 0.29356038 | Q19: =LN(N19)-P19^2/2 -> 11.625199 | R19: =IF(G19<=0,1,NORMSDIST((LN(G19)-Q19-P19^2)/P19)+G19/N19*(1-NORMSDIST((LN(G19)-Q19)/P19))) -> 1 | S19: =IF(F19="—",0,H19*L19*M19*R19) -> 0 | T19: =S19*sig_SAU -> 0 | U19: =S19+T19 -> 0 | V19: =U19/(1-load_SAU) -> 0 | W19: =V19*ea_SAU -> 0 | X19: =V19*ec_SAU -> 0 | Y19: =V19*m_SAU -> 0 | Z19: =V19*tax_SAU -> 0 | AA19: =V19+Z19 -> 0 | AB19: =IF(G19>0,S19/G19*1000,"n.a.") -> n.a.
A20: =B20&"|"&C20 -> Base|EVAC | B20: Base | C20: EVAC | D20: =INDEX(Cov_Nome,MATCH(C20,Cov_Cod,0)) -> Evacuação Médica e Cobertura no Estrangeiro | E20: =INDEX(Cov_Grupo,MATCH(C20,Cov_Cod,0)) -> Extensão | F20: — | G20: 0 | H20: =INDEX(Cov_Lambda,MATCH(C20,Cov_Cod,0)) -> 0.0012 | I20: =INDEX(Cov_Mu,MATCH(C20,Cov_Cod,0)) -> 44700960 | J20: =IF(INDEX(Cov_FR,MATCH(C20,Cov_Cod,0))="S",INDEX(PF_Factor,MATCH("SAU|"&B20,PF_Key,0)),1) -> 1 | K20: =IF(C20="HOSP_INT",los_int,IF(C20="HOSP_CIR",los_cir,0))*MAX(0,room_ref*J20-INDEX(PF_Room,MATCH("SAU|"&B20,PF_Key,0))) -> 0 | L20: =MAX(0,I20*J20-K20) -> 44700960 | M20: =f_trend -> 1.182194 | N20: =H20*L20*M20/(1-EXP(-H20)) -> 52876920 | O20: =INDEX(Cov_CV,MATCH(C20,Cov_Cod,0)) -> 1 | P20: =SQRT(LN(1+O20^2)) -> 0.83255461 | Q20: =LN(N20)-P20^2/2 -> 17.436904 | R20: =IF(G20<=0,1,NORMSDIST((LN(G20)-Q20-P20^2)/P20)+G20/N20*(1-NORMSDIST((LN(G20)-Q20)/P20))) -> 1 | S20: =IF(F20="—",0,H20*L20*M20*R20) -> 0 | T20: =S20*sig_SAU -> 0 | U20: =S20+T20 -> 0 | V20: =U20/(1-load_SAU) -> 0 | W20: =V20*ea_SAU -> 0 | X20: =V20*ec_SAU -> 0 | Y20: =V20*m_SAU -> 0 | Z20: =V20*tax_SAU -> 0 | AA20: =V20+Z20 -> 0 | AB20: =IF(G20>0,S20/G20*1000,"n.a.") -> n.a.
... A24: =B24&"|"&C24 -> Conforto|HOSP_CIR | B24: Conforto | C24: HOSP_CIR | D24: =INDEX(Cov_Nome,MATCH(C24,Cov_Cod,0)) -> Cirurgia (com internamento e de ambulatório) | E24: =INDEX(Cov_Grupo,MATCH(C24,Cov_Cod,0)) -> Principal | F24: B | G24: 15000000 | H24: =INDEX(Cov_Lambda,MATCH(C24,Cov_Cod,0)) -> 0.024 | I24: =INDEX(Cov_Mu,MATCH(C24,Cov_Cod,0)) -> 2032500 | J24: =IF(INDEX(Cov_FR,MATCH(C24,Cov_Cod,0))="S",INDEX(PF_Factor,MATCH("SAU|"&B24,PF_Key,0)),1) -> 1 | K24: =IF(C24="HOSP_INT",los_int,IF(C24="HOSP_CIR",los_cir,0))*MAX(0,room_ref*J24-INDEX(PF_Room,MATCH("SAU|"&B24,PF_Key,0))) -> 0 | L24: =MAX(0,I24*J24-K24) -> 2032500 | M24: =f_trend -> 1.182194 | N24: =H24*L24*M24/(1-EXP(-H24)) -> 2431758.4 | O24: =INDEX(Cov_CV,MATCH(C24,Cov_Cod,0)) -> 1.3 | P24: =SQRT(LN(1+O24^2)) -> 0.99475685 | Q24: =LN(N24)-P24^2/2 -> 14.209355 | R24: =IF(G24<=0,1,NORMSDIST((LN(G24)-Q24-P24^2)/P24)+G24/N24*(1-NORMSDIST((LN(G24)-Q24)/P24))) -> 0.97018645 | S24: =IF(F24="—",0,H24*L24*M24*R24) -> 55948.153 | T24: =S24*sig_SAU -> 4475.8522 | U24: =S24+T24 -> 60424.005 | V24: =U24/(1-load_SAU) -> 86320.007 | W24: =V24*ea_SAU -> 11221.601 | X24: =V24*ec_SAU -> 10358.401 | Y24: =V24*m_SAU -> 4316.0004 | Z24: =V24*tax_SAU -> 863.20007 | AA24: =V24+Z24 -> 87183.207 | AB24: =IF(G24>0,S24/G24*1000,"n.a.") -> 3.7298769
A25: =B25&"|"&C25 -> Conforto|HOSP_UCI | B25: Conforto | C25: HOSP_UCI | D25: =INDEX(Cov_Nome,MATCH(C25,Cov_Cod,0)) -> Cuidados Intensivos (UCI) | E25: =INDEX(Cov_Grupo,MATCH(C25,Cov_Cod,0)) -> Principal | F25: B | G25: =INDEX(PF_UCI,MATCH("SAU|"&B25,PF_Key,0)) -> 6000000 | H25: =INDEX(Cov_Lambda,MATCH(C25,Cov_Cod,0)) -> 0.0035 | I25: =INDEX(Cov_Mu,MATCH(C25,Cov_Cod,0)) -> 2835000 | J25: =IF(INDEX(Cov_FR,MATCH(C25,Cov_Cod,0))="S",INDEX(PF_Factor,MATCH("SAU|"&B25,PF_Key,0)),1) -> 1 | K25: =IF(C25="HOSP_INT",los_int,IF(C25="HOSP_CIR",los_cir,0))*MAX(0,room_ref*J25-INDEX(PF_Room,MATCH("SAU|"&B25,PF_Key,0))) -> 0 | L25: =MAX(0,I25*J25-K25) -> 2835000 | M25: =f_trend -> 1.182194 | N25: =H25*L25*M25/(1-EXP(-H25)) -> 3357388.6 | O25: =INDEX(Cov_CV,MATCH(C25,Cov_Cod,0)) -> 1.2 | P25: =SQRT(LN(1+O25^2)) -> 0.94445648 | Q25: =LN(N25)-P25^2/2 -> 14.580675 | R25: =IF(G25<=0,1,NORMSDIST((LN(G25)-Q25-P25^2)/P25)+G25/N25*(1-NORMSDIST((LN(G25)-Q25)/P25))) -> 0.80422134 | S25: =IF(F25="—",0,H25*L25*M25*R25) -> 9433.7736 | T25: =S25*sig_SAU -> 754.70189 | U25: =S25+T25 -> 10188.476 | V25: =U25/(1-load_SAU) -> 14554.965 | W25: =V25*ea_SAU -> 1892.1455 | X25: =V25*ec_SAU -> 1746.5958 | Y25: =V25*m_SAU -> 727.74825 | Z25: =V25*tax_SAU -> 145.54965 | AA25: =V25+Z25 -> 14700.515 | AB25: =IF(G25>0,S25/G25*1000,"n.a.") -> 1.5722956
A26: =B26&"|"&C26 -> Conforto|AMB_CONS | B26: Conforto | C26: AMB_CONS | D26: =INDEX(Cov_Nome,MATCH(C26,Cov_Cod,0)) -> Consultas de Clínica Geral e Especialidade (incl. teleconsulta) | E26: =INDEX(Cov_Grupo,MATCH(C26,Cov_Cod,0)) -> Principal | F26: B | G26: 3000000 | H26: =INDEX(Cov_Lambda,MATCH(C26,Cov_Cod,0)) -> 2.6 | I26: =INDEX(Cov_Mu,MATCH(C26,Cov_Cod,0)) -> 24000 | J26: =IF(INDEX(Cov_FR,MATCH(C26,Cov_Cod,0))="S",INDEX(PF_Factor,MATCH("SAU|"&B26,PF_Key,0)),1) -> 1 | K26: =IF(C26="HOSP_INT",los_int,IF(C26="HOSP_CIR",los_cir,0))*MAX(0,room_ref*J26-INDEX(PF_Room,MATCH("SAU|"&B26,PF_Key,0))) -> 0 | L26: =MAX(0,I26*J26-K26) -> 24000 | M26: =f_trend -> 1.182194 | N26: =H26*L26*M26/(1-EXP(-H26)) -> 79687.588 | O26: =INDEX(Cov_CV,MATCH(C26,Cov_Cod,0)) -> 1 | P26: =SQRT(LN(1+O26^2)) -> 0.83255461 | Q26: =LN(N26)-P26^2/2 -> 10.939296 | R26: =IF(G26<=0,1,NORMSDIST((LN(G26)-Q26-P26^2)/P26)+G26/N26*(1-NORMSDIST((LN(G26)-Q26)/P26))) -> 0.9999935 | S26: =IF(F26="—",0,H26*L26*M26*R26) -> 73768.426 | T26: =S26*sig_SAU -> 5901.4741 | U26: =S26+T26 -> 79669.9 | V26: =U26/(1-load_SAU) -> 113814.14 | W26: =V26*ea_SAU -> 14795.839 | X26: =V26*ec_SAU -> 13657.697 | Y26: =V26*m_SAU -> 5690.7072 | Z26: =V26*tax_SAU -> 1138.1414 | AA26: =V26+Z26 -> 114952.28 | AB26: =IF(G26>0,S26/G26*1000,"n.a.") -> 24.589475
A27: =B27&"|"&C27 -> Conforto|AMB_MCDT | B27: Conforto | C27: AMB_MCDT | D27: =INDEX(Cov_Nome,MATCH(C27,Cov_Cod,0)) -> MCDT — Exames, Análises e Imagiologia | E27: =INDEX(Cov_Grupo,MATCH(C27,Cov_Cod,0)) -> Principal | F27: B | G27: 3000000 | H27: =INDEX(Cov_Lambda,MATCH(C27,Cov_Cod,0)) -> 3.8 | I27: =INDEX(Cov_Mu,MATCH(C27,Cov_Cod,0)) -> 14600 | J27: =IF(INDEX(Cov_FR,MATCH(C27,Cov_Cod,0))="S",INDEX(PF_Factor,MATCH("SAU|"&B27,PF_Key,0)),1) -> 1 | K27: =IF(C27="HOSP_INT",los_int,IF(C27="HOSP_CIR",los_cir,0))*MAX(0,room_ref*J27-INDEX(PF_Room,MATCH("SAU|"&B27,PF_Key,0))) -> 0 | L27: =MAX(0,I27*J27-K27) -> 14600 | M27: =f_trend -> 1.182194 | N27: =H27*L27*M27/(1-EXP(-H27)) -> 67088.955 | O27: =INDEX(Cov_CV,MATCH(C27,Cov_Cod,0)) -> 1.5 | P27: =SQRT(LN(1+O27^2)) -> 1.0856588 | Q27: =LN(N27)-P27^2/2 -> 10.524447 | R27: =IF(G27<=0,1,NORMSDIST((LN(G27)-Q27-P27^2)/P27)+G27/N27*(1-NORMSDIST((LN(G27)-Q27)/P27))) -> 0.99962836 | S27: =IF(F27="—",0,H27*L27*M27*R27) -> 65563.748 | T27: =S27*sig_SAU -> 5245.0999 | U27: =S27+T27 -> 70808.848 | V27: =U27/(1-load_SAU) -> 101155.5 | W27: =V27*ea_SAU -> 13150.215 | X27: =V27*ec_SAU -> 12138.66 | Y27: =V27*m_SAU -> 5057.7749 | Z27: =V27*tax_SAU -> 1011.555 | AA27: =V27+Z27 -> 102167.05 | AB27: =IF(G27>0,S27/G27*1000,"n.a.") -> 21.854583
A28: =B28&"|"&C28 -> Conforto|MAL | B28: Conforto | C28: MAL | D28: =INDEX(Cov_Nome,MATCH(C28,Cov_Cod,0)) -> Malária e Doenças Endémicas (ambulatório) | E28: =INDEX(Cov_Grupo,MATCH(C28,Cov_Cod,0)) -> Principal | F28: B | G28: 3000000 | H28: =INDEX(Cov_Lambda,MATCH(C28,Cov_Cod,0)) -> 0.3 | I28: =INDEX(Cov_Mu,MATCH(C28,Cov_Cod,0)) -> 36500 | J28: =IF(INDEX(Cov_FR,MATCH(C28,Cov_Cod,0))="S",INDEX(PF_Factor,MATCH("SAU|"&B28,PF_Key,0)),1) -> 1 | K28: =IF(C28="HOSP_INT",los_int,IF(C28="HOSP_CIR",los_cir,0))*MAX(0,room_ref*J28-INDEX(PF_Room,MATCH("SAU|"&B28,PF_Key,0))) -> 0 | L28: =MAX(0,I28*J28-K28) -> 36500 | M28: =f_trend -> 1.182194 | N28: =H28*L28*M28/(1-EXP(-H28)) -> 49945.734 | O28: =INDEX(Cov_CV,MATCH(C28,Cov_Cod,0)) -> 0.8 | P28: =SQRT(LN(1+O28^2)) -> 0.70334646 | Q28: =LN(N28)-P28^2/2 -> 10.571344 | R28: =IF(G28<=0,1,NORMSDIST((LN(G28)-Q28-P28^2)/P28)+G28/N28*(1-NORMSDIST((LN(G28)-Q28)/P28))) -> 1 | S28: =IF(F28="—",0,H28*L28*M28*R28) -> 12945.024 | T28: =S28*sig_SAU -> 1035.6019 | U28: =S28+T28 -> 13980.626 | V28: =U28/(1-load_SAU) -> 19972.323 | W28: =V28*ea_SAU -> 2596.402 | X28: =V28*ec_SAU -> 2396.6788 | Y28: =V28*m_SAU -> 998.61616 | Z28: =V28*tax_SAU -> 199.72323 | AA28: =V28+Z28 -> 20172.046 | AB28: =IF(G28>0,S28/G28*1000,"n.a.") -> 4.3150081
A29: =B29&"|"&C29 -> Conforto|MAT | B29: Conforto | C29: MAT | D29: =INDEX(Cov_Nome,MATCH(C29,Cov_Cod,0)) -> Maternidade e Parto (Normal e Cesariana) | E29: =INDEX(Cov_Grupo,MATCH(C29,Cov_Cod,0)) -> Principal | F29: O | G29: 1000000 | H29: =INDEX(Cov_Lambda,MATCH(C29,Cov_Cod,0)) -> 0.075 | I29: =INDEX(Cov_Mu,MATCH(C29,Cov_Cod,0)) -> 885640 | J29: =IF(INDEX(Cov_FR,MATCH(C29,Cov_Cod,0))="S",INDEX(PF_Factor,MATCH("SAU|"&B29,PF_Key,0)),1) -> 1 | K29: =IF(C29="HOSP_INT",los_int,IF(C29="HOSP_CIR",los_cir,0))*MAX(0,room_ref*J29-INDEX(PF_Room,MATCH("SAU|"&B29,PF_Key,0))) -> 0 | L29: =MAX(0,I29*J29-K29) -> 885640 | M29: =f_trend -> 1.182194 | N29: =H29*L29*M29/(1-EXP(-H29)) -> 1086751.5 | O29: =INDEX(Cov_CV,MATCH(C29,Cov_Cod,0)) -> 0.5 | P29: =SQRT(LN(1+O29^2)) -> 0.47238073 | Q29: =LN(N29)-P29^2/2 -> 13.787132 | R29: =IF(G29<=0,1,NORMSDIST((LN(G29)-Q29-P29^2)/P29)+G29/N29*(1-NORMSDIST((LN(G29)-Q29)/P29))) -> 0.77810443 | S29: =IF(F29="—",0,H29*L29*M29*R29) -> 61100.551 | T29: =S29*sig_SAU -> 4888.0441 | U29: =S29+T29 -> 65988.595 | V29: =U29/(1-load_SAU) -> 94269.421 | W29: =V29*ea_SAU -> 12255.025 | X29: =V29*ec_SAU -> 11312.331 | Y29: =V29*m_SAU -> 4713.4711 | Z29: =V29*tax_SAU -> 942.69421 | AA29: =V29+Z29 -> 95212.115 | AB29: =IF(G29>0,S29/G29*1000,"n.a.") -> 61.100551
A30: =B30&"|"&C30 -> Conforto|URG | B30: Conforto | C30: URG | D30: =INDEX(Cov_Nome,MATCH(C30,Cov_Cod,0)) -> Urgência Hospitalar | E30: =INDEX(Cov_Grupo,MATCH(C30,Cov_Cod,0)) -> Principal | F30: B | G30: 500000 | H30: =INDEX(Cov_Lambda,MATCH(C30,Cov_Cod,0)) -> 0.42 | I30: =INDEX(Cov_Mu,MATCH(C30,Cov_Cod,0)) -> 43300 | J30: =IF(INDEX(Cov_FR,MATCH(C30,Cov_Cod,0))="S",INDEX(PF_Factor,MATCH("SAU|"&B30,PF_Key,0)),1) -> 1 | K30: =IF(C30="HOSP_INT",los_int,IF(C30="HOSP_CIR",los_cir,0))*MAX(0,room_ref*J30-INDEX(PF_Room,MATCH("SAU|"&B30,PF_Key,0))) -> 0 | L30: =MAX(0,I30*J30-K30) -> 43300 | M30: =f_trend -> 1.182194 | N30: =H30*L30*M30/(1-EXP(-H30)) -> 62688.966 | O30: =INDEX(Cov_CV,MATCH(C30,Cov_Cod,0)) -> 1 | P30: =SQRT(LN(1+O30^2)) -> 0.83255461 | Q30: =LN(N30)-P30^2/2 -> 10.699367 | R30: =IF(G30<=0,1,NORMSDIST((LN(G30)-Q30-P30^2)/P30)+G30/N30*(1-NORMSDIST((LN(G30)-Q30)/P30))) -> 0.99553333 | S30: =IF(F30="—",0,H30*L30*M30*R30) -> 21403.35 | T30: =S30*sig_SAU -> 1712.268 | U30: =S30+T30 -> 23115.618 | V30: =U30/(1-load_SAU) -> 33022.311 | W30: =V30*ea_SAU -> 4292.9004 | X30: =V30*ec_SAU -> 3962.6773 | Y30: =V30*m_SAU -> 1651.1155 | Z30: =V30*tax_SAU -> 330.22311 | AA30: =V30+Z30 -> 33352.534 | AB30: =IF(G30>0,S30/G30*1000,"n.a.") -> 42.806699
A31: =B31&"|"&C31 -> Conforto|AMBUL | B31: Conforto | C31: AMBUL | D31: =INDEX(Cov_Nome,MATCH(C31,Cov_Cod,0)) -> Transporte em Ambulância / Emergência Médica | E31: =INDEX(Cov_Grupo,MATCH(C31,Cov_Cod,0)) -> Principal | F31: B | G31: 300000 | H31: =INDEX(Cov_Lambda,MATCH(C31,Cov_Cod,0)) -> 0.018 | I31: =INDEX(Cov_Mu,MATCH(C31,Cov_Cod,0)) -> 76000 | J31: =IF(INDEX(Cov_FR,MATCH(C31,Cov_Cod,0))="S",INDEX(PF_Factor,MATCH("SAU|"&B31,PF_Key,0)),1) -> 1 | K31: =IF(C31="HOSP_INT",los_int,IF(C31="HOSP_CIR",los_cir,0))*MAX(0,room_ref*J31-INDEX(PF_Room,MATCH("SAU|"&B31,PF_Key,0))) -> 0 | L31: =MAX(0,I31*J31-K31) -> 76000 | M31: =f_trend -> 1.182194 | N31: =H31*L31*M31/(1-EXP(-H31)) -> 90657.791 | O31: =INDEX(Cov_CV,MATCH(C31,Cov_Cod,0)) -> 0.6 | P31: =SQRT(LN(1+O31^2)) -> 0.55451303 | Q31: =LN(N31)-P31^2/2 -> 11.261105 | R31: =IF(G31<=0,1,NORMSDIST((LN(G31)-Q31-P31^2)/P31)+G31/N31*(1-NORMSDIST((LN(G31)-Q31)/P31))) -> 0.99461869 | S31: =IF(F31="—",0,H31*L31*M31*R31) -> 1608.5385 | T31: =S31*sig_SAU -> 128.68308 | U31: =S31+T31 -> 1737.2216 | V31: =U31/(1-load_SAU) -> 2481.7451 | W31: =V31*ea_SAU -> 322.62687 | X31: =V31*ec_SAU -> 297.80942 | Y31: =V31*m_SAU -> 124.08726 | Z31: =V31*tax_SAU -> 24.817451 | AA31: =V31+Z31 -> 2506.5626 | AB31: =IF(G31>0,S31/G31*1000,"n.a.") -> 5.3617951
A32: =B32&"|"&C32 -> Conforto|MED | B32: Conforto | C32: MED | D32: =INDEX(Cov_Nome,MATCH(C32,Cov_Cod,0)) -> Medicamentos em Ambulatório (Farmácia) | E32: =INDEX(Cov_Grupo,MATCH(C32,Cov_Cod,0)) -> Principal | F32: O | G32: 400000 | H32: =INDEX(Cov_Lambda,MATCH(C32,Cov_Cod,0)) -> 3.4 | I32: =INDEX(Cov_Mu,MATCH(C32,Cov_Cod,0)) -> 17400 | J32: =IF(INDEX(Cov_FR,MATCH(C32,Cov_Cod,0))="S",INDEX(PF_Factor,MATCH("SAU|"&B32,PF_Key,0)),1) -> 1 | K32: =IF(C32="HOSP_INT",los_int,IF(C32="HOSP_CIR",los_cir,0))*MAX(0,room_ref*J32-INDEX(PF_Room,MATCH("SAU|"&B32,PF_Key,0))) -> 0 | L32: =MAX(0,I32*J32-K32) -> 17400 | M32: =f_trend -> 1.182194 | N32: =H32*L32*M32/(1-EXP(-H32)) -> 72353.262 | O32: =INDEX(Cov_CV,MATCH(C32,Cov_Cod,0)) -> 1.2 | P32: =SQRT(LN(1+O32^2)) -> 0.94445648 | Q32: =LN(N32)-P32^2/2 -> 10.743317 | R32: =IF(G32<=0,1,NORMSDIST((LN(G32)-Q32-P32^2)/P32)+G32/N32*(1-NORMSDIST((LN(G32)-Q32)/P32))) -> 0.9716427 | S32: =IF(F32="—",0,H32*L32*M32*R32) -> 67955.327 | T32: =S32*sig_SAU -> 5436.4262 | U32: =S32+T32 -> 73391.753 | V32: =U32/(1-load_SAU) -> 104845.36 | W32: =V32*ea_SAU -> 13629.897 | X32: =V32*ec_SAU -> 12581.443 | Y32: =V32*m_SAU -> 5242.2681 | Z32: =V32*tax_SAU -> 1048.4536 | AA32: =V32+Z32 -> 105893.82 | AB32: =IF(G32>0,S32/G32*1000,"n.a.") -> 169.88832
A33: =B33&"|"&C33 -> Conforto|DENT | B33: Conforto | C33: DENT | D33: =INDEX(Cov_Nome,MATCH(C33,Cov_Cod,0)) -> Estomatologia (tratamentos) | E33: =INDEX(Cov_Grupo,MATCH(C33,Cov_Cod,0)) -> Extensão | F33: O | G33: 250000 | H33: =INDEX(Cov_Lambda,MATCH(C33,Cov_Cod,0)) -> 0.85 | I33: =INDEX(Cov_Mu,MATCH(C33,Cov_Cod,0)) -> 34500 | J33: =IF(INDEX(Cov_FR,MATCH(C33,Cov_Cod,0))="S",INDEX(PF_Factor,MATCH("SAU|"&B33,PF_Key,0)),1) -> 1 | K33: =IF(C33="HOSP_INT",los_int,IF(C33="HOSP_CIR",los_cir,0))*MAX(0,room_ref*J33-INDEX(PF_Room,MATCH("SAU|"&B33,PF_Key,0))) -> 0 | L33: =MAX(0,I33*J33-K33) -> 34500 | M33: =f_trend -> 1.182194 | N33: =H33*L33*M33/(1-EXP(-H33)) -> 60546.181 | O33: =INDEX(Cov_CV,MATCH(C33,Cov_Cod,0)) -> 1 | P33: =SQRT(LN(1+O33^2)) -> 0.83255461 | Q33: =LN(N33)-P33^2/2 -> 10.664588 | R33: =IF(G33<=0,1,NORMSDIST((LN(G33)-Q33-P33^2)/P33)+G33/N33*(1-NORMSDIST((LN(G33)-Q33)/P33))) -> 0.97123727 | S33: =IF(F33="—",0,H33*L33*M33*R33) -> 33670.697 | T33: =S33*sig_SAU -> 2693.6558 | U33: =S33+T33 -> 36364.353 | V33: =U33/(1-load_SAU) -> 51949.076 | W33: =V33*ea_SAU -> 6753.3799 | X33: =V33*ec_SAU -> 6233.8891 | Y33: =V33*m_SAU -> 2597.4538 | Z33: =V33*tax_SAU -> 519.49076 | AA33: =V33+Z33 -> 52468.567 | AB33: =IF(G33>0,S33/G33*1000,"n.a.") -> 134.68279
A34: =B34&"|"&C34 -> Conforto|PROT | B34: Conforto | C34: PROT | D34: =INDEX(Cov_Nome,MATCH(C34,Cov_Cod,0)) -> Próteses Dentárias | E34: =INDEX(Cov_Grupo,MATCH(C34,Cov_Cod,0)) -> Extensão | F34: O | G34: 150000 | H34: =INDEX(Cov_Lambda,MATCH(C34,Cov_Cod,0)) -> 0.02 | I34: =INDEX(Cov_Mu,MATCH(C34,Cov_Cod,0)) -> 304000 | J34: =IF(INDEX(Cov_FR,MATCH(C34,Cov_Cod,0))="S",INDEX(PF_Factor,MATCH("SAU|"&B34,PF_Key,0)),1) -> 1 | K34: =IF(C34="HOSP_INT",los_int,IF(C34="HOSP_CIR",los_cir,0))*MAX(0,room_ref*J34-INDEX(PF_Room,MATCH("SAU|"&B34,PF_Key,0))) -> 0 | L34: =MAX(0,I34*J34-K34) -> 304000 | M34: =f_trend -> 1.182194 | N34: =H34*L34*M34/(1-EXP(-H34)) -> 362992.83 | O34: =INDEX(Cov_CV,MATCH(C34,Cov_Cod,0)) -> 0.7 | P34: =SQRT(LN(1+O34^2)) -> 0.63148723 | Q34: =LN(N34)-P34^2/2 -> 12.60275 | R34: =IF(G34<=0,1,NORMSDIST((LN(G34)-Q34-P34^2)/P34)+G34/N34*(1-NORMSDIST((LN(G34)-Q34)/P34))) -> 0.39884475 | S34: =IF(F34="—",0,H34*L34*M34*R34) -> 2866.7922 | T34: =S34*sig_SAU -> 229.34337 | U34: =S34+T34 -> 3096.1355 | V34: =U34/(1-load_SAU) -> 4423.0508 | W34: =V34*ea_SAU -> 574.9966 | X34: =V34*ec_SAU -> 530.76609 | Y34: =V34*m_SAU -> 221.15254 | Z34: =V34*tax_SAU -> 44.230508 | AA34: =V34+Z34 -> 4467.2813 | AB34: =IF(G34>0,S34/G34*1000,"n.a.") -> 19.111948
A35: =B35&"|"&C35 -> Conforto|OPT | B35: Conforto | C35: OPT | D35: =INDEX(Cov_Nome,MATCH(C35,Cov_Cod,0)) -> Óptica — Lentes e Armações | E35: =INDEX(Cov_Grupo,MATCH(C35,Cov_Cod,0)) -> Extensão | F35: O | G35: 100000 | H35: =INDEX(Cov_Lambda,MATCH(C35,Cov_Cod,0)) -> 0.22 | I35: =INDEX(Cov_Mu,MATCH(C35,Cov_Cod,0)) -> 102500 | J35: =IF(INDEX(Cov_FR,MATCH(C35,Cov_Cod,0))="S",INDEX(PF_Factor,MATCH("SAU|"&B35,PF_Key,0)),1) -> 1 | K35: =IF(C35="HOSP_INT",los_int,IF(C35="HOSP_CIR",los_cir,0))*MAX(0,room_ref*J35-INDEX(PF_Room,MATCH("SAU|"&B35,PF_Key,0))) -> 0 | L35: =MAX(0,I35*J35-K35) -> 102500 | M35: =f_trend -> 1.182194 | N35: =H35*L35*M35/(1-EXP(-H35)) -> 134992.47 | O35: =INDEX(Cov_CV,MATCH(C35,Cov_Cod,0)) -> 0.5 | P35: =SQRT(LN(1+O35^2)) -> 0.47238073 | Q35: =LN(N35)-P35^2/2 -> 11.701402 | R35: =IF(G35<=0,1,NORMSDIST((LN(G35)-Q35-P35^2)/P35)+G35/N35*(1-NORMSDIST((LN(G35)-Q35)/P35))) -> 0.67702497 | S35: =IF(F35="—",0,H35*L35*M35*R35) -> 18048.453 | T35: =S35*sig_SAU -> 1443.8762 | U35: =S35+T35 -> 19492.329 | V35: =U35/(1-load_SAU) -> 27846.185 | W35: =V35*ea_SAU -> 3620.004 | X35: =V35*ec_SAU -> 3341.5422 | Y35: =V35*m_SAU -> 1392.3092 | Z35: =V35*tax_SAU -> 278.46185 | AA35: =V35+Z35 -> 28124.646 | AB35: =IF(G35>0,S35/G35*1000,"n.a.") -> 180.48453
A36: =B36&"|"&C36 -> Conforto|PREV | B36: Conforto | C36: PREV | D36: =INDEX(Cov_Nome,MATCH(C36,Cov_Cod,0)) -> Medicina Preventiva e Check-up Anual | E36: =INDEX(Cov_Grupo,MATCH(C36,Cov_Cod,0)) -> Extensão | F36: O | G36: 120000 | H36: =INDEX(Cov_Lambda,MATCH(C36,Cov_Cod,0)) -> 0.55 | I36: =INDEX(Cov_Mu,MATCH(C36,Cov_Cod,0)) -> 76000 | J36: =IF(INDEX(Cov_FR,MATCH(C36,Cov_Cod,0))="S",INDEX(PF_Factor,MATCH("SAU|"&B36,PF_Key,0)),1) -> 1 | K36: =IF(C36="HOSP_INT",los_int,IF(C36="HOSP_CIR",los_cir,0))*MAX(0,room_ref*J36-INDEX(PF_Room,MATCH("SAU|"&B36,PF_Key,0))) -> 0 | L36: =MAX(0,I36*J36-K36) -> 76000 | M36: =f_trend -> 1.182194 | N36: =H36*L36*M36/(1-EXP(-H36)) -> 116808.15 | O36: =INDEX(Cov_CV,MATCH(C36,Cov_Cod,0)) -> 0.3 | P36: =SQRT(LN(1+O36^2)) -> 0.29356038 | Q36: =LN(N36)-P36^2/2 -> 11.625199 | R36: =IF(G36<=0,1,NORMSDIST((LN(G36)-Q36-P36^2)/P36)+G36/N36*(1-NORMSDIST((LN(G36)-Q36)/P36))) -> 0.89487911 | S36: =IF(F36="—",0,H36*L36*M36*R36) -> 44221.086 | T36: =S36*sig_SAU -> 3537.6869 | U36: =S36+T36 -> 47758.772 | V36: =U36/(1-load_SAU) -> 68226.818 | W36: =V36*ea_SAU -> 8869.4863 | X36: =V36*ec_SAU -> 8187.2181 | Y36: =V36*m_SAU -> 3411.3409 | Z36: =V36*tax_SAU -> 682.26818 | AA36: =V36+Z36 -> 68909.086 | AB36: =IF(G36>0,S36/G36*1000,"n.a.") -> 368.50905
A37: =B37&"|"&C37 -> Conforto|EVAC | B37: Conforto | C37: EVAC | D37: =INDEX(Cov_Nome,MATCH(C37,Cov_Cod,0)) -> Evacuação Médica e Cobertura no Estrangeiro | E37: =INDEX(Cov_Grupo,MATCH(C37,Cov_Cod,0)) -> Extensão | F37: O | G37: 20000000 | H37: =INDEX(Cov_Lambda,MATCH(C37,Cov_Cod,0)) -> 0.0012 | I37: =INDEX(Cov_Mu,MATCH(C37,Cov_Cod,0)) -> 44700960 | J37: =IF(INDEX(Cov_FR,MATCH(C37,Cov_Cod,0))="S",INDEX(PF_Factor,MATCH("SAU|"&B37,PF_Key,0)),1) -> 1 | K37: =IF(C37="HOSP_INT",los_int,IF(C37="HOSP_CIR",los_cir,0))*MAX(0,room_ref*J37-INDEX(PF_Room,MATCH("SAU|"&B37,PF_Key,0))) -> 0 | L37: =MAX(0,I37*J37-K37) -> 44700960 | M37: =f_trend -> 1.182194 | N37: =H37*L37*M37/(1-EXP(-H37)) -> 52876920 | O37: =INDEX(Cov_CV,MATCH(C37,Cov_Cod,0)) -> 1 | P37: =SQRT(LN(1+O37^2)) -> 0.83255461 | Q37: =LN(N37)-P37^2/2 -> 17.436904 | R37: =IF(G37<=0,1,NORMSDIST((LN(G37)-Q37-P37^2)/P37)+G37/N37*(1-NORMSDIST((LN(G37)-Q37)/P37))) -> 0.34927944 | S37: =IF(F37="—",0,H37*L37*M37*R37) -> 22149.293 | T37: =S37*sig_SAU -> 1771.9434 | U37: =S37+T37 -> 23921.236 | V37: =U37/(1-load_SAU) -> 34173.195 | W37: =V37*ea_SAU -> 4442.5153 | X37: =V37*ec_SAU -> 4100.7834 | Y37: =V37*m_SAU -> 1708.6597 | Z37: =V37*tax_SAU -> 341.73195 | AA37: =V37+Z37 -> 34514.927 | AB37: =IF(G37>0,S37/G37*1000,"n.a.") -> 1.1074647
... A41: =B41&"|"&C41 -> Premium|HOSP_CIR | B41: Premium | C41: HOSP_CIR | D41: =INDEX(Cov_Nome,MATCH(C41,Cov_Cod,0)) -> Cirurgia (com internamento e de ambulatório) | E41: =INDEX(Cov_Grupo,MATCH(C41,Cov_Cod,0)) -> Principal | F41: B | G41: 40000000 | H41: =INDEX(Cov_Lambda,MATCH(C41,Cov_Cod,0)) -> 0.024 | I41: =INDEX(Cov_Mu,MATCH(C41,Cov_Cod,0)) -> 2032500 | J41: =IF(INDEX(Cov_FR,MATCH(C41,Cov_Cod,0))="S",INDEX(PF_Factor,MATCH("SAU|"&B41,PF_Key,0)),1) -> 1.3 | K41: =IF(C41="HOSP_INT",los_int,IF(C41="HOSP_CIR",los_cir,0))*MAX(0,room_ref*J41-INDEX(PF_Room,MATCH("SAU|"&B41,PF_Key,0))) -> 0 | L41: =MAX(0,I41*J41-K41) -> 2642250 | M41: =f_trend -> 1.182194 | N41: =H41*L41*M41/(1-EXP(-H41)) -> 3161285.9 | O41: =INDEX(Cov_CV,MATCH(C41,Cov_Cod,0)) -> 1.3 | P41: =SQRT(LN(1+O41^2)) -> 0.99475685 | Q41: =LN(N41)-P41^2/2 -> 14.471719 | R41: =IF(G41<=0,1,NORMSDIST((LN(G41)-Q41-P41^2)/P41)+G41/N41*(1-NORMSDIST((LN(G41)-Q41)/P41))) -> 0.99454993 | S41: =IF(F41="—",0,H41*L41*M41*R41) -> 74559.072 | T41: =S41*sig_SAU -> 5964.7257 | U41: =S41+T41 -> 80523.797 | V41: =U41/(1-load_SAU) -> 115034 | W41: =V41*ea_SAU -> 14954.42 | X41: =V41*ec_SAU -> 13804.08 | Y41: =V41*m_SAU -> 5751.6998 | Z41: =V41*tax_SAU -> 1150.34 | AA41: =V41+Z41 -> 116184.34 | AB41: =IF(G41>0,S41/G41*1000,"n.a.") -> 1.8639768
A42: =B42&"|"&C42 -> Premium|HOSP_UCI | B42: Premium | C42: HOSP_UCI | D42: =INDEX(Cov_Nome,MATCH(C42,Cov_Cod,0)) -> Cuidados Intensivos (UCI) | E42: =INDEX(Cov_Grupo,MATCH(C42,Cov_Cod,0)) -> Principal | F42: B | G42: =INDEX(PF_UCI,MATCH("SAU|"&B42,PF_Key,0)) -> 15000000 | H42: =INDEX(Cov_Lambda,MATCH(C42,Cov_Cod,0)) -> 0.0035 | I42: =INDEX(Cov_Mu,MATCH(C42,Cov_Cod,0)) -> 2835000 | J42: =IF(INDEX(Cov_FR,MATCH(C42,Cov_Cod,0))="S",INDEX(PF_Factor,MATCH("SAU|"&B42,PF_Key,0)),1) -> 1.3 | K42: =IF(C42="HOSP_INT",los_int,IF(C42="HOSP_CIR",los_cir,0))*MAX(0,room_ref*J42-INDEX(PF_Room,MATCH("SAU|"&B42,PF_Key,0))) -> 0 | L42: =MAX(0,I42*J42-K42) -> 3685500 | M42: =f_trend -> 1.182194 | N42: =H42*L42*M42/(1-EXP(-H42)) -> 4364605.1 | O42: =INDEX(Cov_CV,MATCH(C42,Cov_Cod,0)) -> 1.2 | P42: =SQRT(LN(1+O42^2)) -> 0.94445648 | Q42: =LN(N42)-P42^2/2 -> 14.843039 | R42: =IF(G42<=0,1,NORMSDIST((LN(G42)-Q42-P42^2)/P42)+G42/N42*(1-NORMSDIST((LN(G42)-Q42)/P42))) -> 0.92730223 | S42: =IF(F42="—",0,H42*L42*M42*R42) -> 14140.817 | T42: =S42*sig_SAU -> 1131.2654 | U42: =S42+T42 -> 15272.083 | V42: =U42/(1-load_SAU) -> 21817.261 | W42: =V42*ea_SAU -> 2836.244 | X42: =V42*ec_SAU -> 2618.0714 | Y42: =V42*m_SAU -> 1090.8631 | Z42: =V42*tax_SAU -> 218.17261 | AA42: =V42+Z42 -> 22035.434 | AB42: =IF(G42>0,S42/G42*1000,"n.a.") -> 0.94272117
A43: =B43&"|"&C43 -> Premium|AMB_CONS | B43: Premium | C43: AMB_CONS | D43: =INDEX(Cov_Nome,MATCH(C43,Cov_Cod,0)) -> Consultas de Clínica Geral e Especialidade (incl. teleconsulta) | E43: =INDEX(Cov_Grupo,MATCH(C43,Cov_Cod,0)) -> Principal | F43: B | G43: 8000000 | H43: =INDEX(Cov_Lambda,MATCH(C43,Cov_Cod,0)) -> 2.6 | I43: =INDEX(Cov_Mu,MATCH(C43,Cov_Cod,0)) -> 24000 | J43: =IF(INDEX(Cov_FR,MATCH(C43,Cov_Cod,0))="S",INDEX(PF_Factor,MATCH("SAU|"&B43,PF_Key,0)),1) -> 1.3 | K43: =IF(C43="HOSP_INT",los_int,IF(C43="HOSP_CIR",los_cir,0))*MAX(0,room_ref*J43-INDEX(PF_Room,MATCH("SAU|"&B43,PF_Key,0))) -> 0 | L43: =MAX(0,I43*J43-K43) -> 31200 | M43: =f_trend -> 1.182194 | N43: =H43*L43*M43/(1-EXP(-H43)) -> 103593.86 | O43: =INDEX(Cov_CV,MATCH(C43,Cov_Cod,0)) -> 1 | P43: =SQRT(LN(1+O43^2)) -> 0.83255461 | Q43: =LN(N43)-P43^2/2 -> 11.20166 | R43: =IF(G43<=0,1,NORMSDIST((LN(G43)-Q43-P43^2)/P43)+G43/N43*(1-NORMSDIST((LN(G43)-Q43)/P43))) -> 0.99999989 | S43: =IF(F43="—",0,H43*L43*M43*R43) -> 95899.567 | T43: =S43*sig_SAU -> 7671.9654 | U43: =S43+T43 -> 103571.53 | V43: =U43/(1-load_SAU) -> 147959.33 | W43: =V43*ea_SAU -> 19234.713 | X43: =V43*ec_SAU -> 17755.12 | Y43: =V43*m_SAU -> 7397.9666 | Z43: =V43*tax_SAU -> 1479.5933 | AA43: =V43+Z43 -> 149438.93 | AB43: =IF(G43>0,S43/G43*1000,"n.a.") -> 11.987446
A44: =B44&"|"&C44 -> Premium|AMB_MCDT | B44: Premium | C44: AMB_MCDT | D44: =INDEX(Cov_Nome,MATCH(C44,Cov_Cod,0)) -> MCDT — Exames, Análises e Imagiologia | E44: =INDEX(Cov_Grupo,MATCH(C44,Cov_Cod,0)) -> Principal | F44: B | G44: 8000000 | H44: =INDEX(Cov_Lambda,MATCH(C44,Cov_Cod,0)) -> 3.8 | I44: =INDEX(Cov_Mu,MATCH(C44,Cov_Cod,0)) -> 14600 | J44: =IF(INDEX(Cov_FR,MATCH(C44,Cov_Cod,0))="S",INDEX(PF_Factor,MATCH("SAU|"&B44,PF_Key,0)),1) -> 1.3 | K44: =IF(C44="HOSP_INT",los_int,IF(C44="HOSP_CIR",los_cir,0))*MAX(0,room_ref*J44-INDEX(PF_Room,MATCH("SAU|"&B44,PF_Key,0))) -> 0 | L44: =MAX(0,I44*J44-K44) -> 18980 | M44: =f_trend -> 1.182194 | N44: =H44*L44*M44/(1-EXP(-H44)) -> 87215.641 | O44: =INDEX(Cov_CV,MATCH(C44,Cov_Cod,0)) -> 1.5 | P44: =SQRT(LN(1+O44^2)) -> 1.0856588 | Q44: =LN(N44)-P44^2/2 -> 10.786811 | R44: =IF(G44<=0,1,NORMSDIST((LN(G44)-Q44-P44^2)/P44)+G44/N44*(1-NORMSDIST((LN(G44)-Q44)/P44))) -> 0.99996875 | S44: =IF(F44="—",0,H44*L44*M44*R44) -> 85261.896 | T44: =S44*sig_SAU -> 6820.9517 | U44: =S44+T44 -> 92082.848 | V44: =U44/(1-load_SAU) -> 131546.93 | W44: =V44*ea_SAU -> 17101.1 | X44: =V44*ec_SAU -> 15785.631 | Y44: =V44*m_SAU -> 6577.3463 | Z44: =V44*tax_SAU -> 1315.4693 | AA44: =V44+Z44 -> 132862.39 | AB44: =IF(G44>0,S44/G44*1000,"n.a.") -> 10.657737
A45: =B45&"|"&C45 -> Premium|MAL | B45: Premium | C45: MAL | D45: =INDEX(Cov_Nome,MATCH(C45,Cov_Cod,0)) -> Malária e Doenças Endémicas (ambulatório) | E45: =INDEX(Cov_Grupo,MATCH(C45,Cov_Cod,0)) -> Principal | F45: B | G45: 8000000 | H45: =INDEX(Cov_Lambda,MATCH(C45,Cov_Cod,0)) -> 0.3 | I45: =INDEX(Cov_Mu,MATCH(C45,Cov_Cod,0)) -> 36500 | J45: =IF(INDEX(Cov_FR,MATCH(C45,Cov_Cod,0))="S",INDEX(PF_Factor,MATCH("SAU|"&B45,PF_Key,0)),1) -> 1.3 | K45: =IF(C45="HOSP_INT",los_int,IF(C45="HOSP_CIR",los_cir,0))*MAX(0,room_ref*J45-INDEX(PF_Room,MATCH("SAU|"&B45,PF_Key,0))) -> 0 | L45: =MAX(0,I45*J45-K45) -> 47450 | M45: =f_trend -> 1.182194 | N45: =H45*L45*M45/(1-EXP(-H45)) -> 64929.455 | O45: =INDEX(Cov_CV,MATCH(C45,Cov_Cod,0)) -> 0.8 | P45: =SQRT(LN(1+O45^2)) -> 0.70334646 | Q45: =LN(N45)-P45^2/2 -> 10.833709 | R45: =IF(G45<=0,1,NORMSDIST((LN(G45)-Q45-P45^2)/P45)+G45/N45*(1-NORMSDIST((LN(G45)-Q45)/P45))) -> 1 | S45: =IF(F45="—",0,H45*L45*M45*R45) -> 16828.532 | T45: =S45*sig_SAU -> 1346.2825 | U45: =S45+T45 -> 18174.814 | V45: =U45/(1-load_SAU) -> 25964.02 | W45: =V45*ea_SAU -> 3375.3226 | X45: =V45*ec_SAU -> 3115.6824 | Y45: =V45*m_SAU -> 1298.201 | Z45: =V45*tax_SAU -> 259.6402 | AA45: =V45+Z45 -> 26223.66 | AB45: =IF(G45>0,S45/G45*1000,"n.a.") -> 2.1035664
